Workbook

Sheet Acct1_Raw
A1: Service | B1: Relational Database Service($) | C1: S3($) | D1: DMS($) | E1: Glue($) | F1: EC2-Instances($) | G1: Lambda($) | H1: CloudFront($) | I1: Route53($) | J1: CloudWatch($) | K1: SNS($) | L1: SQS($) | M1: DynamoDB($) | N1: ElastiCache($) | O1: ECS($) | P1: EKS($) | Q1: ECR($) | R1: VPC($) | S1: Direct Connect($) | T1: API Gateway($) | U1: Kinesis($) | V1: Firehose($) | W1: Athena($) | X1: Redshift($) | Y1: EMR($) | Z1: SageMaker($) | AA1: Rekognition($) | AB1: Textract($) | AC1: Comprehend($) | AD1: Translate($) | AE1: Polly($) | AF1: Transcribe($) | AG1: Lex($) | AH1: Connect($) | AI1: Chime($) | AJ1: WorkSpaces($) | AK1: AppStream($) | AL1: WAF($) | AM1: Shield($) | AN1: GuardDuty($) | AO1: Inspector($) | AP1: Macie($) | AQ1: Security Hub($) | AR1: Config($) | AS1: CloudTrail($) | AT1: Systems Manager($) | AU1: Secrets Manager($) | AV1: KMS($) | AW1: ACM($) | AX1: IAM($) | AY1: Organizations($) | AZ1: Control Tower($) | BA1: Service Catalog($) | BB1: CodePipeline($) | BC1: CodeBuild($) | BD1: CodeDeploy($) | BE1: CodeCommit($) | BF1: Amplify($) | BG1: AppSync($) | BH1: EventBridge($) | BI1: Step Functions($) | BJ1: Batch($) | BK1: Fargate($) | BL1: Lightsail($) | BM1: Transfer Family($) | BN1: DataSync($) | BO1: Backup($) | BP1: Total($)
A2: Service total | B2: 54634.461 | C2: 2570.572 | D2: 24257.961 | E2: 19600.221 | F2: 62600.036 | G2: 66509.019 | H2: 86409.898 | I2: 8062.016 | J2: 39511.087 | K2: 3195.743 | L2: 21816.55 | M2: 45402.021 | N2: 2832.546 | O2: 17444.887 | P2: 59420.127 | Q2: 46977.557 | R2: 20650.936 | S2: 57519.581 | T2: 71495.073 | U2: 1114.693 | V2: 79868.491 | W2: 63133.719 | X2: 28480.529 | Y2: 13186.517 | Z2: 79447.163 | AA2: 31473.856 | AB2: 9410.882 | AC2: 9102.495 | AD2: 69699.668 | AE2: 53281.027 | AF2: 79976.555 | AG2: 66221.388 | AH2: 53111.906 | AI2: 93917.161 | AJ2: 31075.96 | AK2: 52157.551 | AL2: 77465.303 | AM2: 56308.962 | AN2: 74016.017 | AO2: 53687.354 | AP2: 58648.542 | AQ2: 4635.422 | AR2: 20779.985 | AS2: 28873.902 | AT2: 8314.727 | AU2: 20398.266 | AV2: 9630.657 | AW2: 23815.124 | AX2: 62169.648 | AY2: 35677.426 | AZ2: 32335.931 | BA2: 19867.105 | BB2: 25001.07 | BC2: 78481.227 | BD2: 61607.544 | BE2: 55489.925 | BF2: 16785.816 | BG2: 66183.293 | BH2: 13689.104 | BI2: 33309.173 | BJ2: 80503.982 | BK2: 62777.73 | BL2: 54208.165 | BM2: 65904.199 | BN2: 73027.064 | BO2: 63787.609 | BP2: 2862950.1
A3: 45870 | B3: 10719.241 | C3: 536.037 | D3: 3676.117 | E3: 3411.442 | F3: 9642.334 | G3: 10978.922 | H3: 14461.61 | I3: 1239.827 | J3: 6339.276 | K3: 552.106 | L3: 3121.045 | M3: 8482.27 | N3: 483.963 | O3: 2797.88 | P3: 9898.611 | Q3: 8786.612 | R3: 3081.123 | S3: 8378.468 | T3: 13966.895 | U3: 205.682 | V3: 11881.886 | W3: 10557.653 | X3: 4581.941 | Y3: 2217.052 | Z3: 13664.827 | AA3: 5250.775 | AB3: 1361.929 | AC3: 1411.724 | AD3: 11089.589 | AE3: 9453.253 | AF3: 11140.139 | AG3: 12307.606 | AH3: 8962.612 | AI3: 12719.854 | AJ3: 5288.993 | AK3: 8747.448 | AL3: 11390.107 | AM3: 8288.336 | AN3: 14630.025 | AO3: 8888.024 | AP3: 10511.23 | AQ3: 849.622 | AR3: 3818.158 | AS3: 4002.118 | AT3: 1133.046 | AU3: 3494.769 | AV3: 1568.126 | AW3: 4199.844 | AX3: 10229.492 | AY3: 5823.923 | AZ3: 6431.374 | BA3: 2833.527 | BB3: 3958.837 | BC3: 13378.517 | BD3: 10814.241 | BE3: 8484.149 | BF3: 2403.685 | BG3: 10794.969 | BH3: 2475.295 | BI3: 5371.618 | BJ3: 13729.744 | BK3: 10859.572 | BL3: 8255.265 | BM3: 11417.403 | BN3: 12849.606 | BO3: 10090.033 | BP3: 474371.4
A4: 45901 | B4: 11069.506 | C4: 520.308 | D4: 4788.582 | E4: 3864.04 | F4: 12231.798 | G4: 9163.454 | H4: 13335.781 | I4: 1275.558 | J4: 6197.029 | K4: 471.951 | L4: 3235.794 | M4: 8740.636 | N4: 460.491 | O4: 3323.686 | P4: 9651.228 | Q4: 8029.773 | R4: 3848.912 | S4: 10199.873 | T4: 12363.965 | U4: 209.728 | V4: 10852.925 | W4: 9861.768 | X4: 5896.663 | Y4: 2474.05 | Z4: 14544.283 | AA4: 5495.796 | AB4: 1285.04 | AC4: 1579.991 | AD4: 12738.55 | AE4: 10057.969 | AF4: 10879.998 | AG4: 12489.842 | AH4: 7070.754 | AI4: 13223.392 | AJ4: 5903.817 | AK4: 8763.02 | AL4: 11468.47 | AM4: 8253.61 | AN4: 14454.462 | AO4: 8039.975 | AP4: 10898.638 | AQ4: 810.818 | AR4: 3410.975 | AS4: 4522.626 | AT4: 1297.71 | AU4: 4033.97 | AV4: 1462.529 | AW4: 4516.92 | AX4: 8821.332 | AY4: 5362.921 | AZ4: 5904.944 | BA4: 3028.353 | BB4: 3853.082 | BC4: 15118.227 | BD4: 8504.681 | BE4: 9061.22 | BF4: 3046.232 | BG4: 12595.748 | BH4: 2210.201 | BI4: 5258.743 | BJ4: 13798.296 | BK4: 10888.462 | BL4: 9358.163 | BM4: 11472.783 | BN4: 12163.016 | BO4: 10464.951 | BP4: 480182.01
A5: 45931 | B5: 10591.394 | C5: 501.522 | D5: 4338.582 | E5: 3926.595 | F5: 11584.934 | G5: 8679.297 | H5: 14667.614 | I5: 1311.405 | J5: 6699.686 | K5: 615.609 | L5: 2989.323 | M5: 6749.534 | N5: 436.985 | O5: 3111.583 | P5: 9115.124 | Q5: 8478.127 | R5: 3605.522 | S5: 8090.437 | T5: 12650.235 | U5: 182.895 | V5: 12065.054 | W5: 11779.364 | X5: 5706.512 | Y5: 2121.064 | Z5: 14033.182 | AA5: 4772.557 | AB5: 1261.202 | AC5: 1666.418 | AD5: 13251.206 | AE5: 8445.976 | AF5: 13003.776 | AG5: 11143.13 | AH5: 7914.299 | AI5: 12451.863 | AJ5: 5008.711 | AK5: 9282.26 | AL5: 13967.788 | AM5: 9443.359 | AN5: 14238.274 | AO5: 8917.96 | AP5: 9479.257 | AQ5: 695.294 | AR5: 3294.604 | AS5: 4939.958 | AT5: 1403.402 | AU5: 3954.743 | AV5: 1796.994 | AW5: 3872.867 | AX5: 8852.47 | AY5: 4876.319 | AZ5: 6087.611 | BA5: 3592.92 | BB5: 3963.433 | BC5: 14564.964 | BD5: 8744.702 | BE5: 10359.435 | BF5: 2939.824 | BG5: 12530.325 | BH5: 2771.011 | BI5: 6412.274 | BJ5: 12727.691 | BK5: 10319.857 | BL5: 7975.732 | BM5: 11632.071 | BN5: 13806.246 | BO5: 12936.157 | BP5: 483330.52
A6: 45962 | B6: 10524.977 | C6: 439.594 | D6: 4559.851 | E6: 3023.059 | F6: 12309.769 | G6: 11278.27 | H6: 12278.202 | I6: 1527.917 | J6: 6310.576 | K6: 512.187 | L6: 3655.211 | M6: 7006.277 | N6: 424.595 | O6: 2780.727 | P6: 9279.23 | Q6: 9118.082 | R6: 3858.63 | S6: 8291.644 | T6: 12676.661 | U6: 190.908 | V6: 13854.248 | W6: 10616.381 | X6: 5850.954 | Y6: 2137.77 | Z6: 16389.31 | AA6: 4621.996 | AB6: 1687.544 | AC6: 1432.644 | AD6: 11232.43 | AE6: 8916.965 | AF6: 12957.627 | AG6: 10359.648 | AH6: 8347.561 | AI6: 14649.456 | AJ6: 5542.463 | AK6: 8516.693 | AL6: 11541.42 | AM6: 9899.454 | AN6: 11005.083 | AO6: 9813.623 | AP6: 10720.376 | AQ6: 834.313 | AR6: 3749.419 | AS6: 4637.718 | AT6: 1236.399 | AU6: 3108.209 | AV6: 1683.998 | AW6: 4025.729 | AX6: 9037.355 | AY6: 6113.983 | AZ6: 5985.918 | BA6: 3028.667 | BB6: 3844.65 | BC6: 13669.86 | BD6: 9470.081 | BE6: 8613.528 | BF6: 2353.663 | BG6: 10702.322 | BH6: 2869.554 | BI6: 6059.966 | BJ6: 16637.659 | BK6: 9969.927 | BL6: 7897.031 | BM6: 10448.889 | BN6: 10761.261 | BO6: 10916.87 | BP6: 477796.98
A7: 45992 | B7: 9424.96 | C7: 484.002 | D7: 4392.77 | E7: 3389.857 | F7: 10881.274 | G7: 9308.224 | H7: 13285.737 | I7: 1563.33 | J7: 6953.816 | K7: 490.074 | L7: 2939.465 | M7: 7665.162 | N7: 515.143 | O7: 2911.251 | P7: 10717.846 | Q7: 8838.907 | R7: 3560.017 | S7: 8146.497 | T7: 11062.893 | U7: 168.749 | V7: 11179.972 | W7: 10423.939 | X7: 5712.148 | Y7: 2106.948 | Z7: 13993.823 | AA7: 5314.394 | AB7: 1346.067 | AC7: 1631.853 | AD7: 12706.196 | AE7: 8396.94 | AF7: 12693.929 | AG7: 9345.306 | AH7: 8698.874 | AI7: 15782.181 | AJ7: 5062.686 | AK7: 8138.449 | AL7: 11246.776 | AM7: 10595.86 | AN7: 13009.142 | AO7: 7528.273 | AP7: 9800.712 | AQ7: 864.585 | AR7: 3450.026 | AS7: 4810.825 | AT7: 1353.698 | AU7: 4090.91 | AV7: 1650.879 | AW7: 4814.501 | AX7: 10695.681 | AY7: 5723.092 | AZ7: 5985.109 | BA7: 3226.273 | BB7: 4482.385 | BC7: 14258.022 | BD7: 10918.243 | BE7: 9846.79 | BF7: 2629.832 | BG7: 10171.923 | BH7: 2342.496 | BI7: 5991.513 | BJ7: 16027.611 | BK7: 9697.57 | BL7: 8717.902 | BM7: 9604.208 | BN7: 11053.966 | BO7: 10912.722 | BP7: 474735.2
A8: 46023 | B8: 8968.118 | C8: 447.095 | D8: 4248.504 | E8: 3054.178 | F8: 10180.665 | G8: 10775.309 | H8: 14222.876 | I8: 1212.968 | J8: 6209.596 | K8: 550.932 | L8: 3272.864 | M8: 6958.756 | N8: 483.518 | O8: 3434.648 | P8: 10030.05 | Q8: 8701.766 | R8: 3746.78 | S8: 9587.607 | T8: 11724.125 | U8: 167.655 | V8: 11568.293 | W8: 11300.897 | X8: 5717.902 | Y8: 2745.379 | Z8: 14013.558 | AA8: 5495.091 | AB8: 1502.422 | AC8: 1588.81 | AD8: 11660.599 | AE8: 8329.916 | AF8: 11892.791 | AG8: 9422.6 | AH8: 7692.095 | AI8: 15384.035 | AJ8: 5575.391 | AK8: 7488.814 | AL8: 12336.252 | AM8: 8275.245 | AN8: 13414.014 | AO8: 7467.568 | AP8: 10261.165 | AQ8: 797.905 | AR8: 2999.754 | AS8: 4600.819 | AT8: 1148.036 | AU8: 3527.58 | AV8: 1388.394 | AW8: 4087.961 | AX8: 8743.728 | AY8: 5248.425 | AZ8: 6055.792 | BA8: 3104.831 | BB8: 4386.276 | BC8: 15455.827 | BD8: 9030.696 | BE8: 8025.117 | BF8: 2267.88 | BG8: 11093.646 | BH8: 2914.832 | BI8: 5494.893 | BJ8: 15512.515 | BK8: 10448.985 | BL8: 8780.907 | BM8: 11086.39 | BN8: 14365.916 | BO8: 10610.546 | BP8: 472288.5

Sheet Acct2_Raw
A1: Service | B1: Relational Database Service($) | C1: S3($) | D1: DMS($) | E1: Glue($) | F1: EC2-Instances($) | G1: Lambda($) | H1: CloudFront($) | I1: Route53($) | J1: CloudWatch($) | K1: SNS($) | L1: SQS($) | M1: DynamoDB($) | N1: ElastiCache($) | O1: ECS($) | P1: EKS($) | Q1: ECR($) | R1: VPC($) | S1: Direct Connect($) | T1: API Gateway($) | U1: Kinesis($) | V1: Firehose($) | W1: Athena($) | X1: Redshift($) | Y1: EMR($) | Z1: SageMaker($) | AA1: Rekognition($) | AB1: Textract($) | AC1: Comprehend($) | AD1: Translate($) | AE1: Polly($) | AF1: Transcribe($) | AG1: Lex($) | AH1: Connect($) | AI1: Chime($) | AJ1: WorkSpaces($) | AK1: AppStream($) | AL1: WAF($) | AM1: Shield($) | AN1: GuardDuty($) | AO1: Inspector($) | AP1: Macie($) | AQ1: Security Hub($) | AR1: Config($) | AS1: CloudTrail($) | AT1: Systems Manager($) | AU1: Secrets Manager($) | AV1: KMS($) | AW1: ACM($) | AX1: IAM($) | AY1: Organizations($) | AZ1: Control Tower($) | BA1: Service Catalog($) | BB1: CodePipeline($) | BC1: CodeBuild($) | BD1: CodeDeploy($) | BE1: CodeCommit($) | BF1: Amplify($) | BG1: AppSync($) | BH1: EventBridge($) | BI1: Step Functions($) | BJ1: Batch($) | BK1: Fargate($) | BL1: Lightsail($) | BM1: Transfer Family($) | BN1: DataSync($) | BO1: Backup($) | BP1: Total($)
A2: Service total | B2: 55859.312 | C2: 66208.262 | D2: 46089.558 | E2: 48133.683 | F2: 33536.154 | G2: 82390.927 | H2: 25591.611 | I2: 8492.748 | J2: 15860.747 | K2: 46149.767 | L2: 81773.745 | M2: 44171.148 | N2: 4272.455 | O2: 24151.186 | P2: 8632.52 | Q2: 26290.596 | R2: 30115.969 | S2: 89157.66 | T2: 48023.915 | U2: 77760.722 | V2: 77001.727 | W2: 10905.133 | X2: 13328.324 | Y2: 85931.348 | Z2: 1015.105 | AA2: 41424.242 | AB2: 64982.802 | AC2: 21453.139 | AD2: 68228.944 | AE2: 74821.604 | AF2: 78999.392 | AG2: 29544.305 | AH2: 23355.999 | AI2: 30370.471 | AJ2: 3472.252 | AK2: 2599.511 | AL2: 21217.32 | AM2: 17178.338 | AN2: 63673.442 | AO2: 31874.19 | AP2: 5000.685 | AQ2: 29340.297 | AR2: 11165.981 | AS2: 2570.355 | AT2: 53615.247 | AU2: 22481.161 | AV2: 23684.128 | AW2: 16681.628 | AX2: 59218.188 | AY2: 64379.922 | AZ2: 92618.417 | BA2: 79214.059 | BB2: 21089.409 | BC2: 56730.102 | BD2: 25129.477 | BE2: 12508.267 | BF2: 41899.573 | BG2: 87673.043 | BH2: 29815.843 | BI2: 45830.589 | BJ2: 70010.662 | BK2: 7535.836 | BL2: 1199.364 | BM2: 84939.778 | BN2: 79360.156 | BO2: 61879.021 | BP2: 2709611.5
A3: 45870 | B3: 7898.098 | C3: 8927.59 | D3: 7967.424 | E3: 7065.866 | F3: 5133.419 | G3: 11187.475 | H3: 4120.433 | I3: 1510.105 | J3: 2748.396 | K3: 7936.271 | L3: 14973.54 | M3: 9124.385 | N3: 718.748 | O3: 3314.026 | P3: 1514.846 | Q3: 4912.813 | R3: 4668.925 | S3: 13331.391 | T3: 7216.727 | U3: 11355.949 | V3: 11466.074 | W3: 2053.301 | X3: 1819.557 | Y3: 14376.949 | Z3: 154.545 | AA3: 7561.849 | AB3: 11218.648 | AC3: 3614.896 | AD3: 11317.451 | AE3: 12798.692 | AF3: 14128.784 | AG3: 4487.099 | AH3: 3803.23 | AI3: 5216.507 | AJ3: 502.34 | AK3: 487.019 | AL3: 3672.031 | AM3: 2665.919 | AN3: 12012.646 | AO3: 5287.608 | AP3: 1022.227 | AQ3: 4995.328 | AR3: 1988.796 | AS3: 401.206 | AT3: 9272.859 | AU3: 4110.269 | AV3: 4615.064 | AW3: 2886.477 | AX3: 8025.743 | AY3: 12635.014 | AZ3: 12572.796 | BA3: 14886.216 | BB3: 3903.414 | BC3: 9929.547 | BD3: 4299.51 | BE3: 1950.759 | BF3: 7148.863 | BG3: 14367.663 | BH3: 5719.498 | BI3: 8323.423 | BJ3: 12410.901 | BK3: 1361.646 | BL3: 175.933 | BM3: 14398.88 | BN3: 13090.782 | BO3: 9030.618 | BP3: 447795
A4: 45901 | B4: 7596.897 | C4: 9268.954 | D4: 6790.932 | E4: 8153.059 | F4: 5149.737 | G4: 13633.146 | H4: 3648.681 | I4: 1743.431 | J4: 2463.461 | K4: 7675.444 | L4: 11209.926 | M4: 7779.739 | N4: 678.232 | O4: 3377.53 | P4: 1365.381 | Q4: 4420.502 | R4: 4474.725 | S4: 12849.22 | T4: 6337.681 | U4: 12378.144 | V4: 12655.27 | W4: 1654.192 | X4: 1847.866 | Y4: 14312.5 | Z4: 181.468 | AA4: 6574.922 | AB4: 11817.905 | AC4: 3207.623 | AD4: 11873.515 | AE4: 12278.082 | AF4: 12282.106 | AG4: 3965.718 | AH4: 4400.507 | AI4: 4564.86 | AJ4: 479.741 | AK4: 433.15 | AL4: 3313.456 | AM4: 2784.284 | AN4: 9961.73 | AO4: 4930.822 | AP4: 788.509 | AQ4: 4167.48 | AR4: 1894.061 | AS4: 467.396 | AT4: 9353.237 | AU4: 3361.99 | AV4: 4099.656 | AW4: 2551.972 | AX4: 8227.403 | AY4: 10164.525 | AZ4: 15348.839 | BA4: 12210.292 | BB4: 3162.482 | BC4: 8344.085 | BD4: 4161.362 | BE4: 1797.211 | BF4: 8152.294 | BG4: 14098.042 | BH4: 6023.96 | BI4: 8812.195 | BJ4: 11089.226 | BK4: 1379.31 | BL4: 207.919 | BM4: 13630.938 | BN4: 14413.818 | BO4: 10828.068 | BP4: 433250.81
A5: 45931 | B5: 7489.551 | C5: 10298.611 | D5: 6863.146 | E5: 6431.837 | F5: 4553.487 | G5: 13201.623 | H5: 4306.469 | I5: 1528.405 | J5: 2670.448 | K5: 7474.942 | L5: 11676.622 | M5: 6905.741 | N5: 763.133 | O5: 3319.038 | P5: 1733.295 | Q5: 4774.336 | R5: 5424.851 | S5: 15107.134 | T5: 8046.277 | U5: 11458.732 | V5: 10845.309 | W5: 2120.294 | X5: 2127.275 | Y5: 15196.368 | Z5: 184.277 | AA5: 6289.953 | AB5: 11724.439 | AC5: 3160.007 | AD5: 12150.703 | AE5: 14413.834 | AF5: 11119.388 | AG5: 3961.071 | AH5: 3638.733 | AI5: 5563.655 | AJ5: 599.416 | AK5: 446.019 | AL5: 3242.532 | AM5: 2452.259 | AN5: 10706.872 | AO5: 4691.537 | AP5: 900.823 | AQ5: 4276.882 | AR5: 2207.34 | AS5: 432.542 | AT5: 9820.879 | AU5: 4186.376 | AV5: 4178.312 | AW5: 3073.91 | AX5: 8121.087 | AY5: 13524.201 | AZ5: 12208.183 | BA5: 15251.396 | BB5: 3296.194 | BC5: 9606.575 | BD5: 3768.661 | BE5: 2165.14 | BF5: 7409.972 | BG5: 14199.5 | BH5: 5877.175 | BI5: 8318.185 | BJ5: 12977.242 | BK5: 1144.364 | BL5: 203.055 | BM5: 11272.852 | BN5: 14765.119 | BO5: 9491.574 | BP5: 441339.16
A6: 45962 | B6: 7486.077 | C6: 8975.088 | D6: 8061.765 | E6: 7021.635 | F6: 5139.045 | G6: 13839.889 | H6: 3498.844 | I6: 1567.877 | J6: 2578.171 | K6: 8883.767 | L6: 13833.364 | M6: 7984.761 | N6: 774.68 | O6: 4352.396 | P6: 1492.167 | Q6: 4126.654 | R6: 4709.501 | S6: 14060.159 | T6: 6395.85 | U6: 13429.625 | V6: 11889.15 | W6: 1836.538 | X6: 2001.208 | Y6: 15981.724 | Z6: 158.039 | AA6: 7665.417 | AB6: 11120.659 | AC6: 3851.749 | AD6: 10510.451 | AE6: 12989.169 | AF6: 14310.163 | AG6: 4417.53 | AH6: 4119.155 | AI6: 5291.926 | AJ6: 543.419 | AK6: 445.886 | AL6: 4122.033 | AM6: 2730.734 | AN6: 9908.067 | AO6: 5532.068 | AP6: 1025.729 | AQ6: 5125.762 | AR6: 2026.673 | AS6: 384.455 | AT6: 9967.346 | AU6: 3377.79 | AV6: 3755.853 | AW6: 3245.771 | AX6: 9137.437 | AY6: 13647.896 | AZ6: 15740.205 | BA6: 13679.325 | BB6: 4091.797 | BC6: 10458.523 | BD6: 3730.409 | BE6: 1790.925 | BF6: 6485.981 | BG6: 16075.598 | BH6: 4820.824 | BI6: 8184.618 | BJ6: 11855.182 | BK6: 1163.279 | BL6: 178.461 | BM6: 14612.739 | BN6: 12797.589 | BO6: 9141.707 | BP6: 454138.28
A7: 45992 | B7: 9317.598 | C7: 11077.956 | D7: 7116.244 | E7: 8084.851 | F7: 5282.063 | G7: 11993.522 | H7: 4351.4 | I7: 1349.332 | J7: 2648.311 | K7: 7869.399 | L7: 11212.953 | M7: 9110.288 | N7: 761.958 | O7: 4083.043 | P7: 1776.018 | Q7: 5215.535 | R7: 5300.322 | S7: 12775.282 | T7: 6439.419 | U7: 13050.325 | V7: 10734.303 | W7: 1699.345 | X7: 2364.925 | Y7: 15928.871 | Z7: 154.63 | AA7: 6108.108 | AB7: 13390.889 | AC7: 3368.083 | AD7: 10280.13 | AE7: 13227.697 | AF7: 11695.133 | AG7: 4794.303 | AH7: 3835.288 | AI7: 5222.861 | AJ7: 562.139 | AK7: 392.37 | AL7: 3994.027 | AM7: 2916.963 | AN7: 11013.665 | AO7: 4794.195 | AP7: 816.364 | AQ7: 4536.682 | AR7: 2215.143 | AS7: 398.033 | AT7: 10365.411 | AU7: 3798.254 | AV7: 3654.904 | AW7: 2686.354 | AX7: 9052.765 | AY7: 13499.796 | AZ7: 15782.985 | BA7: 12446.441 | BB7: 3649.779 | BC7: 9853.704 | BD7: 4129.992 | BE7: 2040.537 | BF7: 7580.971 | BG7: 15826.965 | BH7: 5609.512 | BI7: 6999.9 | BJ7: 12496.225 | BK7: 1318.317 | BL7: 159.961 | BM7: 13366.569 | BN7: 13303.025 | BO7: 8520.997 | BP7: 449403.33
A8: 46023 | B8: 10067.384 | C8: 11752.892 | D8: 8175.512 | E8: 7071.832 | F8: 5755.123 | G8: 12914.552 | H8: 3871.446 | I8: 1756.175 | J8: 2744.249 | K8: 7323.111 | L8: 13881.928 | M8: 7703.772 | N8: 729.75 | O8: 3905.578 | P8: 1557.068 | Q8: 4898.09 | R8: 5029.763 | S8: 15251.639 | T8: 8243.276 | U8: 12948.016 | V8: 13047.047 | W8: 2112.433 | X8: 2222.029 | Y8: 14907.991 | Z8: 169.57 | AA8: 6991.086 | AB8: 10895.279 | AC8: 4083.755 | AD8: 9714.62 | AE8: 13551.787 | AF8: 13663.332 | AG8: 4430.411 | AH8: 3870.402 | AI8: 4827.409 | AJ8: 641.513 | AK8: 396.893 | AL8: 3327.782 | AM8: 2563.067 | AN8: 11676.934 | AO8: 4872.982 | AP8: 986.116 | AQ8: 4597.659 | AR8: 1734.689 | AS8: 442.935 | AT8: 9560.971 | AU8: 4104.464 | AV8: 3989.229 | AW8: 3285.221 | AX8: 7794.385 | AY8: 12102.471 | AZ8: 13736.549 | BA8: 12362.894 | BB8: 3150.388 | BC8: 8166.235 | BD8: 4095.459 | BE8: 1928.786 | BF8: 8432.475 | BG8: 15178.999 | BH8: 5621.914 | BI8: 7473.589 | BJ8: 10580.265 | BK8: 1150.749 | BL8: 170.039 | BM8: 13576.395 | BN8: 13517.198 | BO8: 8489.945 | BP8: 449777.5

Sheet Months_Ref
A1: Month (from Acct1_Raw) | C1: N_Months
A2: =IFERROR(IF(Acct1_Raw!$A$3="","",Acct1_Raw!$A$3),"") | C2: =COUNTA(A2:A25)
A3: =IFERROR(IF(Acct1_Raw!$A$4="","",Acct1_Raw!$A$4),"")
A4: =IFERROR(IF(Acct1_Raw!$A$5="","",Acct1_Raw!$A$5),"")
A5: =IFERROR(IF(Acct1_Raw!$A$6="","",Acct1_Raw!$A$6),"")
A6: =IFERROR(IF(Acct1_Raw!$A$7="","",Acct1_Raw!$A$7),"")
A7: =IFERROR(IF(Acct1_Raw!$A$8="","",Acct1_Raw!$A$8),"")
A8: =IFERROR(IF(Acct1_Raw!$A$9="","",Acct1_Raw!$A$9),"")
A9: =IFERROR(IF(Acct1_Raw!$A$10="","",Acct1_Raw!$A$10),"")
A10: =IFERROR(IF(Acct1_Raw!$A$11="","",Acct1_Raw!$A$11),"")
A11: =IFERROR(IF(Acct1_Raw!$A$12="","",Acct1_Raw!$A$12),"")
A12: =IFERROR(IF(Acct1_Raw!$A$13="","",Acct1_Raw!$A$13),"")
A13: =IFERROR(IF(Acct1_Raw!$A$14="","",Acct1_Raw!$A$14),"")
A14: =IFERROR(IF(Acct1_Raw!$A$15="","",Acct1_Raw!$A$15),"")
A15: =IFERROR(IF(Acct1_Raw!$A$16="","",Acct1_Raw!$A$16),"")
A16: =IFERROR(IF(Acct1_Raw!$A$17="","",Acct1_Raw!$A$17),"")
A17: =IFERROR(IF(Acct1_Raw!$A$18="","",Acct1_Raw!$A$18),"")
A18: =IFERROR(IF(Acct1_Raw!$A$19="","",Acct1_Raw!$A$19),"")
A19: =IFERROR(IF(Acct1_Raw!$A$20="","",Acct1_Raw!$A$20),"")
A20: =IFERROR(IF(Acct1_Raw!$A$21="","",Acct1_Raw!$A$21),"")
A21: =IFERROR(IF(Acct1_Raw!$A$22="","",Acct1_Raw!$A$22),"")
A22: =IFERROR(IF(Acct1_Raw!$A$23="","",Acct1_Raw!$A$23),"")
A23: =IFERROR(IF(Acct1_Raw!$A$24="","",Acct1_Raw!$A$24),"")
A24: =IFERROR(IF(Acct1_Raw!$A$25="","",Acct1_Raw!$A$25),"")
A25: =IFERROR(IF(Acct1_Raw!$A$26="","",Acct1_Raw!$A$26),"")

Sheet Service_List
A1: Service | B1: =IF(Months_Ref!$A$2="","—","A1_"&TEXT(Months_Ref!$A$2,"mmm-yy")) | C1: =IF(Months_Ref!$A$3="","—","A1_"&TEXT(Months_Ref!$A$3,"mmm-yy")) | D1: =IF(Months_Ref!$A$4="","—","A1_"&TEXT(Months_Ref!$A$4,"mmm-yy")) | E1: =IF(Months_Ref!$A$5="","—","A1_"&TEXT(Months_Ref!$A$5,"mmm-yy")) | F1: =IF(Months_Ref!$A$6="","—","A1_"&TEXT(Months_Ref!$A$6,"mmm-yy")) | G1: =IF(Months_Ref!$A$7="","—","A1_"&TEXT(Months_Ref!$A$7,"mmm-yy")) | H1: =IF(Months_Ref!$A$2="","—","A2_"&TEXT(Months_Ref!$A$2,"mmm-yy")) | I1: =IF(Months_Ref!$A$3="","—","A2_"&TEXT(Months_Ref!$A$3,"mmm-yy")) | J1: =IF(Months_Ref!$A$4="","—","A2_"&TEXT(Months_Ref!$A$4,"mmm-yy")) | K1: =IF(Months_Ref!$A$5="","—","A2_"&TEXT(Months_Ref!$A$5,"mmm-yy")) | L1: =IF(Months_Ref!$A$6="","—","A2_"&TEXT(Months_Ref!$A$6,"mmm-yy")) | M1: =IF(Months_Ref!$A$7="","—","A2_"&TEXT(Months_Ref!$A$7,"mmm-yy")) | N1: =IF(Months_Ref!$A$2="","—","CB_"&TEXT(Months_Ref!$A$2,"mmm-yy")) | O1: =IF(Months_Ref!$A$3="","—","CB_"&TEXT(Months_Ref!$A$3,"mmm-yy")) | P1: =IF(Months_Ref!$A$4="","—","CB_"&TEXT(Months_Ref!$A$4,"mmm-yy")) | Q1: =IF(Months_Ref!$A$5="","—","CB_"&TEXT(Months_Ref!$A$5,"mmm-yy")) | R1: =IF(Months_Ref!$A$6="","—","CB_"&TEXT(Months_Ref!$A$6,"mmm-yy")) | S1: =IF(Months_Ref!$A$7="","—","CB_"&TEXT(Months_Ref!$A$7,"mmm-yy"))
A2: ACM($) | B2: =IFERROR(IF(Months_Ref!$A$2="",0,INDEX(Acct1_Raw!$B$3:$BO$26,MATCH(Months_Ref!$A$2,Acct1_Raw!$A$3:$A$26,0),MATCH($A2,Acct1_Raw!$B$1:$BO$1,0))),0) | C2: =IFERROR(IF(Months_Ref!$A$3="",0,INDEX(Acct1_Raw!$B$3:$BO$26,MATCH(Months_Ref!$A$3,Acct1_Raw!$A$3:$A$26,0),MATCH($A2,Acct1_Raw!$B$1:$BO$1,0))),0) | D2: =IFERROR(IF(Months_Ref!$A$4="",0,INDEX(Acct1_Raw!$B$3:$BO$26,MATCH(Months_Ref!$A$4,Acct1_Raw!$A$3:$A$26,0),MATCH($A2,Acct1_Raw!$B$1:$BO$1,0))),0) | E2: =IFERROR(IF(Months_Ref!$A$5="",0,INDEX(Acct1_Raw!$B$3:$BO$26,MATCH(Months_Ref!$A$5,Acct1_Raw!$A$3:$A$26,0),MATCH($A2,Acct1_Raw!$B$1:$BO$1,0))),0) | F2: =IFERROR(IF(Months_Ref!$A$6="",0,INDEX(Acct1_Raw!$B$3:$BO$26,MATCH(Months_Ref!$A$6,Acct1_Raw!$A$3:$A$26,0),MATCH($A2,Acct1_Raw!$B$1:$BO$1,0))),0) | G2: =IFERROR(IF(Months_Ref!$A$7="",0,INDEX(Acct1_Raw!$B$3:$BO$26,MATCH(Months_Ref!$A$7,Acct1_Raw!$A$3:$A$26,0),MATCH($A2,Acct1_Raw!$B$1:$BO$1,0))),0) | H2: =IFERROR(IF(Months_Ref!$A$2="",0,INDEX(Acct2_Raw!$B$3:$BO$26,MATCH(Months_Ref!$A$2,Acct2_Raw!$A$3:$A$26,0),MATCH($A2,Acct2_Raw!$B$1:$BO$1,0))),0) | I2: =IFERROR(IF(Months_Ref!$A$3="",0,INDEX(Acct2_Raw!$B$3:$BO$26,MATCH(Months_Ref!$A$3,Acct2_Raw!$A$3:$A$26,0),MATCH($A2,Acct2_Raw!$B$1:$BO$1,0))),0) | J2: =IFERROR(IF(Months_Ref!$A$4="",0,INDEX(Acct2_Raw!$B$3:$BO$26,MATCH(Months_Ref!$A$4,Acct2_Raw!$A$3:$A$26,0),MATCH($A2,Acct2_Raw!$B$1:$BO$1,0))),0) | K2: =IFERROR(IF(Months_Ref!$A$5="",0,INDEX(Acct2_Raw!$B$3:$BO$26,MATCH(Months_Ref!$A$5,Acct2_Raw!$A$3:$A$26,0),MATCH($A2,Acct2_Raw!$B$1:$BO$1,0))),0) | L2: =IFERROR(IF(Months_Ref!$A$6="",0,INDEX(Acct2_Raw!$B$3:$BO$26,MATCH(Months_Ref!$A$6,Acct2_Raw!$A$3:$A$26,0),MATCH($A2,Acct2_Raw!$B$1:$BO$1,0))),0) | M2: =IFERROR(IF(Months_Ref!$A$7="",0,INDEX(Acct2_Raw!$B$3:$BO$26,MATCH(Months_Ref!$A$7,Acct2_Raw!$A$3:$A$26,0),MATCH($A2,Acct2_Raw!$B$1:$BO$1,0))),0) | N2: =B2+H2 | O2: =C2+I2 | P2: =D2+J2 | Q2: =E2+K2 | R2: =F2+L2 | S2: =G2+M2
A3: API Gateway($) | B3: =IFERROR(IF(Months_Ref!$A$2="",0,INDEX(Acct1_Raw!$B$3:$BO$26,MATCH(Months_Ref!$A$2,Acct1_Raw!$A$3:$A$26,0),MATCH($A3,Acct1_Raw!$B$1:$BO$1,0))),0) | C3: =IFERROR(IF(Months_Ref!$A$3="",0,INDEX(Acct1_Raw!$B$3:$BO$26,MATCH(Months_Ref!$A$3,Acct1_Raw!$A$3:$A$26,0),MATCH($A3,Acct1_Raw!$B$1:$BO$1,0))),0) | D3: =IFERROR(IF(Months_Ref!$A$4="",0,INDEX(Acct1_Raw!$B$3:$BO$26,MATCH(Months_Ref!$A$4,Acct1_Raw!$A$3:$A$26,0),MATCH($A3,Acct1_Raw!$B$1:$BO$1,0))),0) | E3: =IFERROR(IF(Months_Ref!$A$5="",0,INDEX(Acct1_Raw!$B$3:$BO$26,MATCH(Months_Ref!$A$5,Acct1_Raw!$A$3:$A$26,0),MATCH($A3,Acct1_Raw!$B$1:$BO$1,0))),0) | F3: =IFERROR(IF(Months_Ref!$A$6="",0,INDEX(Acct1_Raw!$B$3:$BO$26,MATCH(Months_Ref!$A$6,Acct1_Raw!$A$3:$A$26,0),MATCH($A3,Acct1_Raw!$B$1:$BO$1,0))),0) | G3: =IFERROR(IF(Months_Ref!$A$7="",0,INDEX(Acct1_Raw!$B$3:$BO$26,MATCH(Months_Ref!$A$7,Acct1_Raw!$A$3:$A$26,0),MATCH($A3,Acct1_Raw!$B$1:$BO$1,0))),0) | H3: =IFERROR(IF(Months_Ref!$A$2="",0,INDEX(Acct2_Raw!$B$3:$BO$26,MATCH(Months_Ref!$A$2,Acct2_Raw!$A$3:$A$26,0),MATCH($A3,Acct2_Raw!$B$1:$BO$1,0))),0) | I3: =IFERROR(IF(Months_Ref!$A$3="",0,INDEX(Acct2_Raw!$B$3:$BO$26,MATCH(Months_Ref!$A$3,Acct2_Raw!$A$3:$A$26,0),MATCH($A3,Acct2_Raw!$B$1:$BO$1,0))),0) | J3: =IFERROR(IF(Months_Ref!$A$4="",0,INDEX(Acct2_Raw!$B$3:$BO$26,MATCH(Months_Ref!$A$4,Acct2_Raw!$A$3:$A$26,0),MATCH($A3,Acct2_Raw!$B$1:$BO$1,0))),0) | K3: =IFERROR(IF(Months_Ref!$A$5="",0,INDEX(Acct2_Raw!$B$3:$BO$26,MATCH(Months_Ref!$A$5,Acct2_Raw!$A$3:$A$26,0),MATCH($A3,Acct2_Raw!$B$1:$BO$1,0))),0) | L3: =IFERROR(IF(Months_Ref!$A$6="",0,INDEX(Acct2_Raw!$B$3:$BO$26,MATCH(Months_Ref!$A$6,Acct2_Raw!$A$3:$A$26,0),MATCH($A3,Acct2_Raw!$B$1:$BO$1,0))),0) | M3: =IFERROR(IF(Months_Ref!$A$7="",0,INDEX(Acct2_Raw!$B$3:$BO$26,MATCH(Months_Ref!$A$7,Acct2_Raw!$A$3:$A$26,0),MATCH($A3,Acct2_Raw!$B$1:$BO$1,0))),0) | N3: =B3+H3 | O3: =C3+I3 | P3: =D3+J3 | Q3: =E3+K3 | R3: =F3+L3 | S3: =G3+M3
A4: Amplify($) | B4: =IFERROR(IF(Months_Ref!$A$2="",0,INDEX(Acct1_Raw!$B$3:$BO$26,MATCH(Months_Ref!$A$2,Acct1_Raw!$A$3:$A$26,0),MATCH($A4,Acct1_Raw!$B$1:$BO$1,0))),0) | C4: =IFERROR(IF(Months_Ref!$A$3="",0,INDEX(Acct1_Raw!$B$3:$BO$26,MATCH(Months_Ref!$A$3,Acct1_Raw!$A$3:$A$26,0),MATCH($A4,Acct1_Raw!$B$1:$BO$1,0))),0) | D4: =IFERROR(IF(Months_Ref!$A$4="",0,INDEX(Acct1_Raw!$B$3:$BO$26,MATCH(Months_Ref!$A$4,Acct1_Raw!$A$3:$A$26,0),MATCH($A4,Acct1_Raw!$B$1:$BO$1,0))),0) | E4: =IFERROR(IF(Months_Ref!$A$5="",0,INDEX(Acct1_Raw!$B$3:$BO$26,MATCH(Months_Ref!$A$5,Acct1_Raw!$A$3:$A$26,0),MATCH($A4,Acct1_Raw!$B$1:$BO$1,0))),0) | F4: =IFERROR(IF(Months_Ref!$A$6="",0,INDEX(Acct1_Raw!$B$3:$BO$26,MATCH(Months_Ref!$A$6,Acct1_Raw!$A$3:$A$26,0),MATCH($A4,Acct1_Raw!$B$1:$BO$1,0))),0) | G4: =IFERROR(IF(Months_Ref!$A$7="",0,INDEX(Acct1_Raw!$B$3:$BO$26,MATCH(Months_Ref!$A$7,Acct1_Raw!$A$3:$A$26,0),MATCH($A4,Acct1_Raw!$B$1:$BO$1,0))),0) | H4: =IFERROR(IF(Months_Ref!$A$2="",0,INDEX(Acct2_Raw!$B$3:$BO$26,MATCH(Months_Ref!$A$2,Acct2_Raw!$A$3:$A$26,0),MATCH($A4,Acct2_Raw!$B$1:$BO$1,0))),0) | I4: =IFERROR(IF(Months_Ref!$A$3="",0,INDEX(Acct2_Raw!$B$3:$BO$26,MATCH(Months_Ref!$A$3,Acct2_Raw!$A$3:$A$26,0),MATCH($A4,Acct2_Raw!$B$1:$BO$1,0))),0) | J4: =IFERROR(IF(Months_Ref!$A$4="",0,INDEX(Acct2_Raw!$B$3:$BO$26,MATCH(Months_Ref!$A$4,Acct2_Raw!$A$3:$A$26,0),MATCH($A4,Acct2_Raw!$B$1:$BO$1,0))),0) | K4: =IFERROR(IF(Months_Ref!$A$5="",0,INDEX(Acct2_Raw!$B$3:$BO$26,MATCH(Months_Ref!$A$5,Acct2_Raw!$A$3:$A$26,0),MATCH($A4,Acct2_Raw!$B$1:$BO$1,0))),0) | L4: =IFERROR(IF(Months_Ref!$A$6="",0,INDEX(Acct2_Raw!$B$3:$BO$26,MATCH(Months_Ref!$A$6,Acct2_Raw!$A$3:$A$26,0),MATCH($A4,Acct2_Raw!$B$1:$BO$1,0))),0) | M4: =IFERROR(IF(Months_Ref!$A$7="",0,INDEX(Acct2_Raw!$B$3:$BO$26,MATCH(Months_Ref!$A$7,Acct2_Raw!$A$3:$A$26,0),MATCH($A4,Acct2_Raw!$B$1:$BO$1,0))),0) | N4: =B4+H4 | O4: =C4+I4 | P4: =D4+J4 | Q4: =E4+K4 | R4: =F4+L4 | S4: =G4+M4
A5: AppStream($) | B5: =IFERROR(IF(Months_Ref!$A$2="",0,INDEX(Acct1_Raw!$B$3:$BO$26,MATCH(Months_Ref!$A$2,Acct1_Raw!$A$3:$A$26,0),MATCH($A5,Acct1_Raw!$B$1:$BO$1,0))),0) | C5: =IFERROR(IF(Months_Ref!$A$3="",0,INDEX(Acct1_Raw!$B$3:$BO$26,MATCH(Months_Ref!$A$3,Acct1_Raw!$A$3:$A$26,0),MATCH($A5,Acct1_Raw!$B$1:$BO$1,0))),0) | D5: =IFERROR(IF(Months_Ref!$A$4="",0,INDEX(Acct1_Raw!$B$3:$BO$26,MATCH(Months_Ref!$A$4,Acct1_Raw!$A$3:$A$26,0),MATCH($A5,Acct1_Raw!$B$1:$BO$1,0))),0) | E5: =IFERROR(IF(Months_Ref!$A$5="",0,INDEX(Acct1_Raw!$B$3:$BO$26,MATCH(Months_Ref!$A$5,Acct1_Raw!$A$3:$A$26,0),MATCH($A5,Acct1_Raw!$B$1:$BO$1,0))),0) | F5: =IFERROR(IF(Months_Ref!$A$6="",0,INDEX(Acct1_Raw!$B$3:$BO$26,MATCH(Months_Ref!$A$6,Acct1_Raw!$A$3:$A$26,0),MATCH($A5,Acct1_Raw!$B$1:$BO$1,0))),0) | G5: =IFERROR(IF(Months_Ref!$A$7="",0,INDEX(Acct1_Raw!$B$3:$BO$26,MATCH(Months_Ref!$A$7,Acct1_Raw!$A$3:$A$26,0),MATCH($A5,Acct1_Raw!$B$1:$BO$1,0))),0) | H5: =IFERROR(IF(Months_Ref!$A$2="",0,INDEX(Acct2_Raw!$B$3:$BO$26,MATCH(Months_Ref!$A$2,Acct2_Raw!$A$3:$A$26,0),MATCH($A5,Acct2_Raw!$B$1:$BO$1,0))),0) | I5: =IFERROR(IF(Months_Ref!$A$3="",0,INDEX(Acct2_Raw!$B$3:$BO$26,MATCH(Months_Ref!$A$3,Acct2_Raw!$A$3:$A$26,0),MATCH($A5,Acct2_Raw!$B$1:$BO$1,0))),0) | J5: =IFERROR(IF(Months_Ref!$A$4="",0,INDEX(Acct2_Raw!$B$3:$BO$26,MATCH(Months_Ref!$A$4,Acct2_Raw!$A$3:$A$26,0),MATCH($A5,Acct2_Raw!$B$1:$BO$1,0))),0) | K5: =IFERROR(IF(Months_Ref!$A$5="",0,INDEX(Acct2_Raw!$B$3:$BO$26,MATCH(Months_Ref!$A$5,Acct2_Raw!$A$3:$A$26,0),MATCH($A5,Acct2_Raw!$B$1:$BO$1,0))),0) | L5: =IFERROR(IF(Months_Ref!$A$6="",0,INDEX(Acct2_Raw!$B$3:$BO$26,MATCH(Months_Ref!$A$6,Acct2_Raw!$A$3:$A$26,0),MATCH($A5,Acct2_Raw!$B$1:$BO$1,0))),0) | M5: =IFERROR(IF(Months_Ref!$A$7="",0,INDEX(Acct2_Raw!$B$3:$BO$26,MATCH(Months_Ref!$A$7,Acct2_Raw!$A$3:$A$26,0),MATCH($A5,Acct2_Raw!$B$1:$BO$1,0))),0) | N5: =B5+H5 | O5: =C5+I5 | P5: =D5+J5 | Q5: =E5+K5 | R5: =F5+L5 | S5: =G5+M5
A6: AppSync($) | B6: =IFERROR(IF(Months_Ref!$A$2="",0,INDEX(Acct1_Raw!$B$3:$BO$26,MATCH(Months_Ref!$A$2,Acct1_Raw!$A$3:$A$26,0),MATCH($A6,Acct1_Raw!$B$1:$BO$1,0))),0) | C6: =IFERROR(IF(Months_Ref!$A$3="",0,INDEX(Acct1_Raw!$B$3:$BO$26,MATCH(Months_Ref!$A$3,Acct1_Raw!$A$3:$A$26,0),MATCH($A6,Acct1_Raw!$B$1:$BO$1,0))),0) | D6: =IFERROR(IF(Months_Ref!$A$4="",0,INDEX(Acct1_Raw!$B$3:$BO$26,MATCH(Months_Ref!$A$4,Acct1_Raw!$A$3:$A$26,0),MATCH($A6,Acct1_Raw!$B$1:$BO$1,0))),0) | E6: =IFERROR(IF(Months_Ref!$A$5="",0,INDEX(Acct1_Raw!$B$3:$BO$26,MATCH(Months_Ref!$A$5,Acct1_Raw!$A$3:$A$26,0),MATCH($A6,Acct1_Raw!$B$1:$BO$1,0))),0) | F6: =IFERROR(IF(Months_Ref!$A$6="",0,INDEX(Acct1_Raw!$B$3:$BO$26,MATCH(Months_Ref!$A$6,Acct1_Raw!$A$3:$A$26,0),MATCH($A6,Acct1_Raw!$B$1:$BO$1,0))),0) | G6: =IFERROR(IF(Months_Ref!$A$7="",0,INDEX(Acct1_Raw!$B$3:$BO$26,MATCH(Months_Ref!$A$7,Acct1_Raw!$A$3:$A$26,0),MATCH($A6,Acct1_Raw!$B$1:$BO$1,0))),0) | H6: =IFERROR(IF(Months_Ref!$A$2="",0,INDEX(Acct2_Raw!$B$3:$BO$26,MATCH(Months_Ref!$A$2,Acct2_Raw!$A$3:$A$26,0),MATCH($A6,Acct2_Raw!$B$1:$BO$1,0))),0) | I6: =IFERROR(IF(Months_Ref!$A$3="",0,INDEX(Acct2_Raw!$B$3:$BO$26,MATCH(Months_Ref!$A$3,Acct2_Raw!$A$3:$A$26,0),MATCH($A6,Acct2_Raw!$B$1:$BO$1,0))),0) | J6: =IFERROR(IF(Months_Ref!$A$4="",0,INDEX(Acct2_Raw!$B$3:$BO$26,MATCH(Months_Ref!$A$4,Acct2_Raw!$A$3:$A$26,0),MATCH($A6,Acct2_Raw!$B$1:$BO$1,0))),0) | K6: =IFERROR(IF(Months_Ref!$A$5="",0,INDEX(Acct2_Raw!$B$3:$BO$26,MATCH(Months_Ref!$A$5,Acct2_Raw!$A$3:$A$26,0),MATCH($A6,Acct2_Raw!$B$1:$BO$1,0))),0) | L6: =IFERROR(IF(Months_Ref!$A$6="",0,INDEX(Acct2_Raw!$B$3:$BO$26,MATCH(Months_Ref!$A$6,Acct2_Raw!$A$3:$A$26,0),MATCH($A6,Acct2_Raw!$B$1:$BO$1,0))),0) | M6: =IFERROR(IF(Months_Ref!$A$7="",0,INDEX(Acct2_Raw!$B$3:$BO$26,MATCH(Months_Ref!$A$7,Acct2_Raw!$A$3:$A$26,0),MATCH($A6,Acct2_Raw!$B$1:$BO$1,0))),0) | N6: =B6+H6 | O6: =C6+I6 | P6: =D6+J6 | Q6: =E6+K6 | R6: =F6+L6 | S6: =G6+M6
A7: Athena($) | B7: =IFERROR(IF(Months_Ref!$A$2="",0,INDEX(Acct1_Raw!$B$3:$BO$26,MATCH(Months_Ref!$A$2,Acct1_Raw!$A$3:$A$26,0),MATCH($A7,Acct1_Raw!$B$1:$BO$1,0))),0) | C7: =IFERROR(IF(Months_Ref!$A$3="",0,INDEX(Acct1_Raw!$B$3:$BO$26,MATCH(Months_Ref!$A$3,Acct1_Raw!$A$3:$A$26,0),MATCH($A7,Acct1_Raw!$B$1:$BO$1,0))),0) | D7: =IFERROR(IF(Months_Ref!$A$4="",0,INDEX(Acct1_Raw!$B$3:$BO$26,MATCH(Months_Ref!$A$4,Acct1_Raw!$A$3:$A$26,0),MATCH($A7,Acct1_Raw!$B$1:$BO$1,0))),0) | E7: =IFERROR(IF(Months_Ref!$A$5="",0,INDEX(Acct1_Raw!$B$3:$BO$26,MATCH(Months_Ref!$A$5,Acct1_Raw!$A$3:$A$26,0),MATCH($A7,Acct1_Raw!$B$1:$BO$1,0))),0) | F7: =IFERROR(IF(Months_Ref!$A$6="",0,INDEX(Acct1_Raw!$B$3:$BO$26,MATCH(Months_Ref!$A$6,Acct1_Raw!$A$3:$A$26,0),MATCH($A7,Acct1_Raw!$B$1:$BO$1,0))),0) | G7: =IFERROR(IF(Months_Ref!$A$7="",0,INDEX(Acct1_Raw!$B$3:$BO$26,MATCH(Months_Ref!$A$7,Acct1_Raw!$A$3:$A$26,0),MATCH($A7,Acct1_Raw!$B$1:$BO$1,0))),0) | H7: =IFERROR(IF(Months_Ref!$A$2="",0,INDEX(Acct2_Raw!$B$3:$BO$26,MATCH(Months_Ref!$A$2,Acct2_Raw!$A$3:$A$26,0),MATCH($A7,Acct2_Raw!$B$1:$BO$1,0))),0) | I7: =IFERROR(IF(Months_Ref!$A$3="",0,INDEX(Acct2_Raw!$B$3:$BO$26,MATCH(Months_Ref!$A$3,Acct2_Raw!$A$3:$A$26,0),MATCH($A7,Acct2_Raw!$B$1:$BO$1,0))),0) | J7: =IFERROR(IF(Months_Ref!$A$4="",0,INDEX(Acct2_Raw!$B$3:$BO$26,MATCH(Months_Ref!$A$4,Acct2_Raw!$A$3:$A$26,0),MATCH($A7,Acct2_Raw!$B$1:$BO$1,0))),0) | K7: =IFERROR(IF(Months_Ref!$A$5="",0,INDEX(Acct2_Raw!$B$3:$BO$26,MATCH(Months_Ref!$A$5,Acct2_Raw!$A$3:$A$26,0),MATCH($A7,Acct2_Raw!$B$1:$BO$1,0))),0) | L7: =IFERROR(IF(Months_Ref!$A$6="",0,INDEX(Acct2_Raw!$B$3:$BO$26,MATCH(Months_Ref!$A$6,Acct2_Raw!$A$3:$A$26,0),MATCH($A7,Acct2_Raw!$B$1:$BO$1,0))),0) | M7: =IFERROR(IF(Months_Ref!$A$7="",0,INDEX(Acct2_Raw!$B$3:$BO$26,MATCH(Months_Ref!$A$7,Acct2_Raw!$A$3:$A$26,0),MATCH($A7,Acct2_Raw!$B$1:$BO$1,0))),0) | N7: =B7+H7 | O7: =C7+I7 | P7: =D7+J7 | Q7: =E7+K7 | R7: =F7+L7 | S7: =G7+M7
A8: Backup($) | B8: =IFERROR(IF(Months_Ref!$A$2="",0,INDEX(Acct1_Raw!$B$3:$BO$26,MATCH(Months_Ref!$A$2,Acct1_Raw!$A$3:$A$26,0),MATCH($A8,Acct1_Raw!$B$1:$BO$1,0))),0) | C8: =IFERROR(IF(Months_Ref!$A$3="",0,INDEX(Acct1_Raw!$B$3:$BO$26,MATCH(Months_Ref!$A$3,Acct1_Raw!$A$3:$A$26,0),MATCH($A8,Acct1_Raw!$B$1:$BO$1,0))),0) | D8: =IFERROR(IF(Months_Ref!$A$4="",0,INDEX(Acct1_Raw!$B$3:$BO$26,MATCH(Months_Ref!$A$4,Acct1_Raw!$A$3:$A$26,0),MATCH($A8,Acct1_Raw!$B$1:$BO$1,0))),0) | E8: =IFERROR(IF(Months_Ref!$A$5="",0,INDEX(Acct1_Raw!$B$3:$BO$26,MATCH(Months_Ref!$A$5,Acct1_Raw!$A$3:$A$26,0),MATCH($A8,Acct1_Raw!$B$1:$BO$1,0))),0) | F8: =IFERROR(IF(Months_Ref!$A$6="",0,INDEX(Acct1_Raw!$B$3:$BO$26,MATCH(Months_Ref!$A$6,Acct1_Raw!$A$3:$A$26,0),MATCH($A8,Acct1_Raw!$B$1:$BO$1,0))),0) | G8: =IFERROR(IF(Months_Ref!$A$7="",0,INDEX(Acct1_Raw!$B$3:$BO$26,MATCH(Months_Ref!$A$7,Acct1_Raw!$A$3:$A$26,0),MATCH($A8,Acct1_Raw!$B$1:$BO$1,0))),0) | H8: =IFERROR(IF(Months_Ref!$A$2="",0,INDEX(Acct2_Raw!$B$3:$BO$26,MATCH(Months_Ref!$A$2,Acct2_Raw!$A$3:$A$26,0),MATCH($A8,Acct2_Raw!$B$1:$BO$1,0))),0) | I8: =IFERROR(IF(Months_Ref!$A$3="",0,INDEX(Acct2_Raw!$B$3:$BO$26,MATCH(Months_Ref!$A$3,Acct2_Raw!$A$3:$A$26,0),MATCH($A8,Acct2_Raw!$B$1:$BO$1,0))),0) | J8: =IFERROR(IF(Months_Ref!$A$4="",0,INDEX(Acct2_Raw!$B$3:$BO$26,MATCH(Months_Ref!$A$4,Acct2_Raw!$A$3:$A$26,0),MATCH($A8,Acct2_Raw!$B$1:$BO$1,0))),0) | K8: =IFERROR(IF(Months_Ref!$A$5="",0,INDEX(Acct2_Raw!$B$3:$BO$26,MATCH(Months_Ref!$A$5,Acct2_Raw!$A$3:$A$26,0),MATCH($A8,Acct2_Raw!$B$1:$BO$1,0))),0) | L8: =IFERROR(IF(Months_Ref!$A$6="",0,INDEX(Acct2_Raw!$B$3:$BO$26,MATCH(Months_Ref!$A$6,Acct2_Raw!$A$3:$A$26,0),MATCH($A8,Acct2_Raw!$B$1:$BO$1,0))),0) | M8: =IFERROR(IF(Months_Ref!$A$7="",0,INDEX(Acct2_Raw!$B$3:$BO$26,MATCH(Months_Ref!$A$7,Acct2_Raw!$A$3:$A$26,0),MATCH($A8,Acct2_Raw!$B$1:$BO$1,0))),0) | N8: =B8+H8 | O8: =C8+I8 | P8: =D8+J8 | Q8: =E8+K8 | R8: =F8+L8 | S8: =G8+M8
A9: Batch($) | B9: =IFERROR(IF(Months_Ref!$A$2="",0,INDEX(Acct1_Raw!$B$3:$BO$26,MATCH(Months_Ref!$A$2,Acct1_Raw!$A$3:$A$26,0),MATCH($A9,Acct1_Raw!$B$1:$BO$1,0))),0) | C9: =IFERROR(IF(Months_Ref!$A$3="",0,INDEX(Acct1_Raw!$B$3:$BO$26,MATCH(Months_Ref!$A$3,Acct1_Raw!$A$3:$A$26,0),MATCH($A9,Acct1_Raw!$B$1:$BO$1,0))),0) | D9: =IFERROR(IF(Months_Ref!$A$4="",0,INDEX(Acct1_Raw!$B$3:$BO$26,MATCH(Months_Ref!$A$4,Acct1_Raw!$A$3:$A$26,0),MATCH($A9,Acct1_Raw!$B$1:$BO$1,0))),0) | E9: =IFERROR(IF(Months_Ref!$A$5="",0,INDEX(Acct1_Raw!$B$3:$BO$26,MATCH(Months_Ref!$A$5,Acct1_Raw!$A$3:$A$26,0),MATCH($A9,Acct1_Raw!$B$1:$BO$1,0))),0) | F9: =IFERROR(IF(Months_Ref!$A$6="",0,INDEX(Acct1_Raw!$B$3:$BO$26,MATCH(Months_Ref!$A$6,Acct1_Raw!$A$3:$A$26,0),MATCH($A9,Acct1_Raw!$B$1:$BO$1,0))),0) | G9: =IFERROR(IF(Months_Ref!$A$7="",0,INDEX(Acct1_Raw!$B$3:$BO$26,MATCH(Months_Ref!$A$7,Acct1_Raw!$A$3:$A$26,0),MATCH($A9,Acct1_Raw!$B$1:$BO$1,0))),0) | H9: =IFERROR(IF(Months_Ref!$A$2="",0,INDEX(Acct2_Raw!$B$3:$BO$26,MATCH(Months_Ref!$A$2,Acct2_Raw!$A$3:$A$26,0),MATCH($A9,Acct2_Raw!$B$1:$BO$1,0))),0) | I9: =IFERROR(IF(Months_Ref!$A$3="",0,INDEX(Acct2_Raw!$B$3:$BO$26,MATCH(Months_Ref!$A$3,Acct2_Raw!$A$3:$A$26,0),MATCH($A9,Acct2_Raw!$B$1:$BO$1,0))),0) | J9: =IFERROR(IF(Months_Ref!$A$4="",0,INDEX(Acct2_Raw!$B$3:$BO$26,MATCH(Months_Ref!$A$4,Acct2_Raw!$A$3:$A$26,0),MATCH($A9,Acct2_Raw!$B$1:$BO$1,0))),0) | K9: =IFERROR(IF(Months_Ref!$A$5="",0,INDEX(Acct2_Raw!$B$3:$BO$26,MATCH(Months_Ref!$A$5,Acct2_Raw!$A$3:$A$26,0),MATCH($A9,Acct2_Raw!$B$1:$BO$1,0))),0) | L9: =IFERROR(IF(Months_Ref!$A$6="",0,INDEX(Acct2_Raw!$B$3:$BO$26,MATCH(Months_Ref!$A$6,Acct2_Raw!$A$3:$A$26,0),MATCH($A9,Acct2_Raw!$B$1:$BO$1,0))),0) | M9: =IFERROR(IF(Months_Ref!$A$7="",0,INDEX(Acct2_Raw!$B$3:$BO$26,MATCH(Months_Ref!$A$7,Acct2_Raw!$A$3:$A$26,0),MATCH($A9,Acct2_Raw!$B$1:$BO$1,0))),0) | N9: =B9+H9 | O9: =C9+I9 | P9: =D9+J9 | Q9: =E9+K9 | R9: =F9+L9 | S9: =G9+M9
A10: Chime($) | B10: =IFERROR(IF(Months_Ref!$A$2="",0,INDEX(Acct1_Raw!$B$3:$BO$26,MATCH(Months_Ref!$A$2,Acct1_Raw!$A$3:$A$26,0),MATCH($A10,Acct1_Raw!$B$1:$BO$1,0))),0) | C10: =IFERROR(IF(Months_Ref!$A$3="",0,INDEX(Acct1_Raw!$B$3:$BO$26,MATCH(Months_Ref!$A$3,Acct1_Raw!$A$3:$A$26,0),MATCH($A10,Acct1_Raw!$B$1:$BO$1,0))),0) | D10: =IFERROR(IF(Months_Ref!$A$4="",0,INDEX(Acct1_Raw!$B$3:$BO$26,MATCH(Months_Ref!$A$4,Acct1_Raw!$A$3:$A$26,0),MATCH($A10,Acct1_Raw!$B$1:$BO$1,0))),0) | E10: =IFERROR(IF(Months_Ref!$A$5="",0,INDEX(Acct1_Raw!$B$3:$BO$26,MATCH(Months_Ref!$A$5,Acct1_Raw!$A$3:$A$26,0),MATCH($A10,Acct1_Raw!$B$1:$BO$1,0))),0) | F10: =IFERROR(IF(Months_Ref!$A$6="",0,INDEX(Acct1_Raw!$B$3:$BO$26,MATCH(Months_Ref!$A$6,Acct1_Raw!$A$3:$A$26,0),MATCH($A10,Acct1_Raw!$B$1:$BO$1,0))),0) | G10: =IFERROR(IF(Months_Ref!$A$7="",0,INDEX(Acct1_Raw!$B$3:$BO$26,MATCH(Months_Ref!$A$7,Acct1_Raw!$A$3:$A$26,0),MATCH($A10,Acct1_Raw!$B$1:$BO$1,0))),0) | H10: =IFERROR(IF(Months_Ref!$A$2="",0,INDEX(Acct2_Raw!$B$3:$BO$26,MATCH(Months_Ref!$A$2,Acct2_Raw!$A$3:$A$26,0),MATCH($A10,Acct2_Raw!$B$1:$BO$1,0))),0) | I10: =IFERROR(IF(Months_Ref!$A$3="",0,INDEX(Acct2_Raw!$B$3:$BO$26,MATCH(Months_Ref!$A$3,Acct2_Raw!$A$3:$A$26,0),MATCH($A10,Acct2_Raw!$B$1:$BO$1,0))),0) | J10: =IFERROR(IF(Months_Ref!$A$4="",0,INDEX(Acct2_Raw!$B$3:$BO$26,MATCH(Months_Ref!$A$4,Acct2_Raw!$A$3:$A$26,0),MATCH($A10,Acct2_Raw!$B$1:$BO$1,0))),0) | K10: =IFERROR(IF(Months_Ref!$A$5="",0,INDEX(Acct2_Raw!$B$3:$BO$26,MATCH(Months_Ref!$A$5,Acct2_Raw!$A$3:$A$26,0),MATCH($A10,Acct2_Raw!$B$1:$BO$1,0))),0) | L10: =IFERROR(IF(Months_Ref!$A$6="",0,INDEX(Acct2_Raw!$B$3:$BO$26,MATCH(Months_Ref!$A$6,Acct2_Raw!$A$3:$A$26,0),MATCH($A10,Acct2_Raw!$B$1:$BO$1,0))),0) | M10: =IFERROR(IF(Months_Ref!$A$7="",0,INDEX(Acct2_Raw!$B$3:$BO$26,MATCH(Months_Ref!$A$7,Acct2_Raw!$A$3:$A$26,0),MATCH($A10,Acct2_Raw!$B$1:$BO$1,0))),0) | N10: =B10+H10 | O10: =C10+I10 | P10: =D10+J10 | Q10: =E10+K10 | R10: =F10+L10 | S10: =G10+M10
A11: CloudFront($) | B11: =IFERROR(IF(Months_Ref!$A$2="",0,INDEX(Acct1_Raw!$B$3:$BO$26,MATCH(Months_Ref!$A$2,Acct1_Raw!$A$3:$A$26,0),MATCH($A11,Acct1_Raw!$B$1:$BO$1,0))),0) | C11: =IFERROR(IF(Months_Ref!$A$3="",0,INDEX(Acct1_Raw!$B$3:$BO$26,MATCH(Months_Ref!$A$3,Acct1_Raw!$A$3:$A$26,0),MATCH($A11,Acct1_Raw!$B$1:$BO$1,0))),0) | D11: =IFERROR(IF(Months_Ref!$A$4="",0,INDEX(Acct1_Raw!$B$3:$BO$26,MATCH(Months_Ref!$A$4,Acct1_Raw!$A$3:$A$26,0),MATCH($A11,Acct1_Raw!$B$1:$BO$1,0))),0) | E11: =IFERROR(IF(Months_Ref!$A$5="",0,INDEX(Acct1_Raw!$B$3:$BO$26,MATCH(Months_Ref!$A$5,Acct1_Raw!$A$3:$A$26,0),MATCH($A11,Acct1_Raw!$B$1:$BO$1,0))),0) | F11: =IFERROR(IF(Months_Ref!$A$6="",0,INDEX(Acct1_Raw!$B$3:$BO$26,MATCH(Months_Ref!$A$6,Acct1_Raw!$A$3:$A$26,0),MATCH($A11,Acct1_Raw!$B$1:$BO$1,0))),0) | G11: =IFERROR(IF(Months_Ref!$A$7="",0,INDEX(Acct1_Raw!$B$3:$BO$26,MATCH(Months_Ref!$A$7,Acct1_Raw!$A$3:$A$26,0),MATCH($A11,Acct1_Raw!$B$1:$BO$1,0))),0) | H11: =IFERROR(IF(Months_Ref!$A$2="",0,INDEX(Acct2_Raw!$B$3:$BO$26,MATCH(Months_Ref!$A$2,Acct2_Raw!$A$3:$A$26,0),MATCH($A11,Acct2_Raw!$B$1:$BO$1,0))),0) | I11: =IFERROR(IF(Months_Ref!$A$3="",0,INDEX(Acct2_Raw!$B$3:$BO$26,MATCH(Months_Ref!$A$3,Acct2_Raw!$A$3:$A$26,0),MATCH($A11,Acct2_Raw!$B$1:$BO$1,0))),0) | J11: =IFERROR(IF(Months_Ref!$A$4="",0,INDEX(Acct2_Raw!$B$3:$BO$26,MATCH(Months_Ref!$A$4,Acct2_Raw!$A$3:$A$26,0),MATCH($A11,Acct2_Raw!$B$1:$BO$1,0))),0) | K11: =IFERROR(IF(Months_Ref!$A$5="",0,INDEX(Acct2_Raw!$B$3:$BO$26,MATCH(Months_Ref!$A$5,Acct2_Raw!$A$3:$A$26,0),MATCH($A11,Acct2_Raw!$B$1:$BO$1,0))),0) | L11: =IFERROR(IF(Months_Ref!$A$6="",0,INDEX(Acct2_Raw!$B$3:$BO$26,MATCH(Months_Ref!$A$6,Acct2_Raw!$A$3:$A$26,0),MATCH($A11,Acct2_Raw!$B$1:$BO$1,0))),0) | M11: =IFERROR(IF(Months_Ref!$A$7="",0,INDEX(Acct2_Raw!$B$3:$BO$26,MATCH(Months_Ref!$A$7,Acct2_Raw!$A$3:$A$26,0),MATCH($A11,Acct2_Raw!$B$1:$BO$1,0))),0) | N11: =B11+H11 | O11: =C11+I11 | P11: =D11+J11 | Q11: =E11+K11 | R11: =F11+L11 | S11: =G11+M11
A12: CloudTrail($) | B12: =IFERROR(IF(Months_Ref!$A$2="",0,INDEX(Acct1_Raw!$B$3:$BO$26,MATCH(Months_Ref!$A$2,Acct1_Raw!$A$3:$A$26,0),MATCH($A12,Acct1_Raw!$B$1:$BO$1,0))),0) | C12: =IFERROR(IF(Months_Ref!$A$3="",0,INDEX(Acct1_Raw!$B$3:$BO$26,MATCH(Months_Ref!$A$3,Acct1_Raw!$A$3:$A$26,0),MATCH($A12,Acct1_Raw!$B$1:$BO$1,0))),0) | D12: =IFERROR(IF(Months_Ref!$A$4="",0,INDEX(Acct1_Raw!$B$3:$BO$26,MATCH(Months_Ref!$A$4,Acct1_Raw!$A$3:$A$26,0),MATCH($A12,Acct1_Raw!$B$1:$BO$1,0))),0) | E12: =IFERROR(IF(Months_Ref!$A$5="",0,INDEX(Acct1_Raw!$B$3:$BO$26,MATCH(Months_Ref!$A$5,Acct1_Raw!$A$3:$A$26,0),MATCH($A12,Acct1_Raw!$B$1:$BO$1,0))),0) | F12: =IFERROR(IF(Months_Ref!$A$6="",0,INDEX(Acct1_Raw!$B$3:$BO$26,MATCH(Months_Ref!$A$6,Acct1_Raw!$A$3:$A$26,0),MATCH($A12,Acct1_Raw!$B$1:$BO$1,0))),0) | G12: =IFERROR(IF(Months_Ref!$A$7="",0,INDEX(Acct1_Raw!$B$3:$BO$26,MATCH(Months_Ref!$A$7,Acct1_Raw!$A$3:$A$26,0),MATCH($A12,Acct1_Raw!$B$1:$BO$1,0))),0) | H12: =IFERROR(IF(Months_Ref!$A$2="",0,INDEX(Acct2_Raw!$B$3:$BO$26,MATCH(Months_Ref!$A$2,Acct2_Raw!$A$3:$A$26,0),MATCH($A12,Acct2_Raw!$B$1:$BO$1,0))),0) | I12: =IFERROR(IF(Months_Ref!$A$3="",0,INDEX(Acct2_Raw!$B$3:$BO$26,MATCH(Months_Ref!$A$3,Acct2_Raw!$A$3:$A$26,0),MATCH($A12,Acct2_Raw!$B$1:$BO$1,0))),0) | J12: =IFERROR(IF(Months_Ref!$A$4="",0,INDEX(Acct2_Raw!$B$3:$BO$26,MATCH(Months_Ref!$A$4,Acct2_Raw!$A$3:$A$26,0),MATCH($A12,Acct2_Raw!$B$1:$BO$1,0))),0) | K12: =IFERROR(IF(Months_Ref!$A$5="",0,INDEX(Acct2_Raw!$B$3:$BO$26,MATCH(Months_Ref!$A$5,Acct2_Raw!$A$3:$A$26,0),MATCH($A12,Acct2_Raw!$B$1:$BO$1,0))),0) | L12: =IFERROR(IF(Months_Ref!$A$6="",0,INDEX(Acct2_Raw!$B$3:$BO$26,MATCH(Months_Ref!$A$6,Acct2_Raw!$A$3:$A$26,0),MATCH($A12,Acct2_Raw!$B$1:$BO$1,0))),0) | M12: =IFERROR(IF(Months_Ref!$A$7="",0,INDEX(Acct2_Raw!$B$3:$BO$26,MATCH(Months_Ref!$A$7,Acct2_Raw!$A$3:$A$26,0),MATCH($A12,Acct2_Raw!$B$1:$BO$1,0))),0) | N12: =B12+H12 | O12: =C12+I12 | P12: =D12+J12 | Q12: =E12+K12 | R12: =F12+L12 | S12: =G12+M12
A13: CloudWatch($) | B13: =IFERROR(IF(Months_Ref!$A$2="",0,INDEX(Acct1_Raw!$B$3:$BO$26,MATCH(Months_Ref!$A$2,Acct1_Raw!$A$3:$A$26,0),MATCH($A13,Acct1_Raw!$B$1:$BO$1,0))),0) | C13: =IFERROR(IF(Months_Ref!$A$3="",0,INDEX(Acct1_Raw!$B$3:$BO$26,MATCH(Months_Ref!$A$3,Acct1_Raw!$A$3:$A$26,0),MATCH($A13,Acct1_Raw!$B$1:$BO$1,0))),0) | D13: =IFERROR(IF(Months_Ref!$A$4="",0,INDEX(Acct1_Raw!$B$3:$BO$26,MATCH(Months_Ref!$A$4,Acct1_Raw!$A$3:$A$26,0),MATCH($A13,Acct1_Raw!$B$1:$BO$1,0))),0) | E13: =IFERROR(IF(Months_Ref!$A$5="",0,INDEX(Acct1_Raw!$B$3:$BO$26,MATCH(Months_Ref!$A$5,Acct1_Raw!$A$3:$A$26,0),MATCH($A13,Acct1_Raw!$B$1:$BO$1,0))),0) | F13: =IFERROR(IF(Months_Ref!$A$6="",0,INDEX(Acct1_Raw!$B$3:$BO$26,MATCH(Months_Ref!$A$6,Acct1_Raw!$A$3:$A$26,0),MATCH($A13,Acct1_Raw!$B$1:$BO$1,0))),0) | G13: =IFERROR(IF(Months_Ref!$A$7="",0,INDEX(Acct1_Raw!$B$3:$BO$26,MATCH(Months_Ref!$A$7,Acct1_Raw!$A$3:$A$26,0),MATCH($A13,Acct1_Raw!$B$1:$BO$1,0))),0) | H13: =IFERROR(IF(Months_Ref!$A$2="",0,INDEX(Acct2_Raw!$B$3:$BO$26,MATCH(Months_Ref!$A$2,Acct2_Raw!$A$3:$A$26,0),MATCH($A13,Acct2_Raw!$B$1:$BO$1,0))),0) | I13: =IFERROR(IF(Months_Ref!$A$3="",0,INDEX(Acct2_Raw!$B$3:$BO$26,MATCH(Months_Ref!$A$3,Acct2_Raw!$A$3:$A$26,0),MATCH($A13,Acct2_Raw!$B$1:$BO$1,0))),0) | J13: =IFERROR(IF(Months_Ref!$A$4="",0,INDEX(Acct2_Raw!$B$3:$BO$26,MATCH(Months_Ref!$A$4,Acct2_Raw!$A$3:$A$26,0),MATCH($A13,Acct2_Raw!$B$1:$BO$1,0))),0) | K13: =IFERROR(IF(Months_Ref!$A$5="",0,INDEX(Acct2_Raw!$B$3:$BO$26,MATCH(Months_Ref!$A$5,Acct2_Raw!$A$3:$A$26,0),MATCH($A13,Acct2_Raw!$B$1:$BO$1,0))),0) | L13: =IFERROR(IF(Months_Ref!$A$6="",0,INDEX(Acct2_Raw!$B$3:$BO$26,MATCH(Months_Ref!$A$6,Acct2_Raw!$A$3:$A$26,0),MATCH($A13,Acct2_Raw!$B$1:$BO$1,0))),0) | M13: =IFERROR(IF(Months_Ref!$A$7="",0,INDEX(Acct2_Raw!$B$3:$BO$26,MATCH(Months_Ref!$A$7,Acct2_Raw!$A$3:$A$26,0),MATCH($A13,Acct2_Raw!$B$1:$BO$1,0))),0) | N13: =B13+H13 | O13: =C13+I13 | P13: =D13+J13 | Q13: =E13+K13 | R13: =F13+L13 | S13: =G13+M13
... A67: WorkSpaces($) | B67: =IFERROR(IF(Months_Ref!$A$2="",0,INDEX(Acct1_Raw!$B$3:$BO$26,MATCH(Months_Ref!$A$2,Acct1_Raw!$A$3:$A$26,0),MATCH($A67,Acct1_Raw!$B$1:$BO$1,0))),0) | C67: =IFERROR(IF(Months_Ref!$A$3="",0,INDEX(Acct1_Raw!$B$3:$BO$26,MATCH(Months_Ref!$A$3,Acct1_Raw!$A$3:$A$26,0),MATCH($A67,Acct1_Raw!$B$1:$BO$1,0))),0) | D67: =IFERROR(IF(Months_Ref!$A$4="",0,INDEX(Acct1_Raw!$B$3:$BO$26,MATCH(Months_Ref!$A$4,Acct1_Raw!$A$3:$A$26,0),MATCH($A67,Acct1_Raw!$B$1:$BO$1,0))),0) | E67: =IFERROR(IF(Months_Ref!$A$5="",0,INDEX(Acct1_Raw!$B$3:$BO$26,MATCH(Months_Ref!$A$5,Acct1_Raw!$A$3:$A$26,0),MATCH($A67,Acct1_Raw!$B$1:$BO$1,0))),0) | F67: =IFERROR(IF(Months_Ref!$A$6="",0,INDEX(Acct1_Raw!$B$3:$BO$26,MATCH(Months_Ref!$A$6,Acct1_Raw!$A$3:$A$26,0),MATCH($A67,Acct1_Raw!$B$1:$BO$1,0))),0) | G67: =IFERROR(IF(Months_Ref!$A$7="",0,INDEX(Acct1_Raw!$B$3:$BO$26,MATCH(Months_Ref!$A$7,Acct1_Raw!$A$3:$A$26,0),MATCH($A67,Acct1_Raw!$B$1:$BO$1,0))),0) | H67: =IFERROR(IF(Months_Ref!$A$2="",0,INDEX(Acct2_Raw!$B$3:$BO$26,MATCH(Months_Ref!$A$2,Acct2_Raw!$A$3:$A$26,0),MATCH($A67,Acct2_Raw!$B$1:$BO$1,0))),0) | I67: =IFERROR(IF(Months_Ref!$A$3="",0,INDEX(Acct2_Raw!$B$3:$BO$26,MATCH(Months_Ref!$A$3,Acct2_Raw!$A$3:$A$26,0),MATCH($A67,Acct2_Raw!$B$1:$BO$1,0))),0) | J67: =IFERROR(IF(Months_Ref!$A$4="",0,INDEX(Acct2_Raw!$B$3:$BO$26,MATCH(Months_Ref!$A$4,Acct2_Raw!$A$3:$A$26,0),MATCH($A67,Acct2_Raw!$B$1:$BO$1,0))),0) | K67: =IFERROR(IF(Months_Ref!$A$5="",0,INDEX(Acct2_Raw!$B$3:$BO$26,MATCH(Months_Ref!$A$5,Acct2_Raw!$A$3:$A$26,0),MATCH($A67,Acct2_Raw!$B$1:$BO$1,0))),0) | L67: =IFERROR(IF(Months_Ref!$A$6="",0,INDEX(Acct2_Raw!$B$3:$BO$26,MATCH(Months_Ref!$A$6,Acct2_Raw!$A$3:$A$26,0),MATCH($A67,Acct2_Raw!$B$1:$BO$1,0))),0) | M67: =IFERROR(IF(Months_Ref!$A$7="",0,INDEX(Acct2_Raw!$B$3:$BO$26,MATCH(Months_Ref!$A$7,Acct2_Raw!$A$3:$A$26,0),MATCH($A67,Acct2_Raw!$B$1:$BO$1,0))),0) | N67: =B67+H67 | O67: =C67+I67 | P67: =D67+J67 | Q67: =E67+K67 | R67: =F67+L67 | S67: =G67+M67

Sheet Chart_Engine
A1: Month | B1: A1_col | C1: A2_col | D1: CB_col
A2: =Months_Ref!$A$2 | B2: 2 | C2: 8 | D2: 14
A3: =Months_Ref!$A$3 | B3: 3 | C3: 9 | D3: 15
A4: =Months_Ref!$A$4 | B4: 4 | C4: 10 | D4: 16
A5: =Months_Ref!$A$5 | B5: 5 | C5: 11 | D5: 17
A6: =Months_Ref!$A$6 | B6: 6 | C6: 12 | D6: 18
A7: =Months_Ref!$A$7 | B7: 7 | C7: 13 | D7: 19
A28: curr_col | B28: =IF(Dashboard!$E$5="Acct1",IFERROR(INDEX($B$2:$B$7,IFERROR(MATCH(Dashboard!$K$5,$A$2:$A$7,0),1)),2),IF(Dashboard!$E$5="Acct2",IFERROR(INDEX($C$2:$C$7,IFERROR(MATCH(Dashboard!$K$5,$A$2:$A$7,0),1)),8),IFERROR(INDEX($D$2:$D$7,IFERROR(MATCH(Dashboard!$K$5,$A$2:$A$7,0),1)),14)))
A29: prior_col | B29: =IF(Dashboard!$E$5="Acct1",IFERROR(INDEX($B$2:$B$7,IFERROR(MATCH(Dashboard!$Q$5,$A$2:$A$7,0),1)),2),IF(Dashboard!$E$5="Acct2",IFERROR(INDEX($C$2:$C$7,IFERROR(MATCH(Dashboard!$Q$5,$A$2:$A$7,0),1)),8),IFERROR(INDEX($D$2:$D$7,IFERROR(MATCH(Dashboard!$Q$5,$A$2:$A$7,0),1)),14))) | E29: Service | F29: Curr($) | G29: Prior($) | H29: MoM_D | I29: MoM_P | J29: Rank_Curr | K29: AbsMoM | L29: Rank_MoM | N29: Rank | O29: Service | P29: Curr($) | Q29: Prior($) | R29: MoM_D | S29: MoM_P | U29: Rank | V29: Service | W29: Curr($) | X29: Prior($) | Y29: MoM_D | Z29: MoM_P | AB29: Month | AC29: Acct1($) | AD29: Acct2($) | AE29: Comb($) | AG29: Service | AH29: Cost($) | AJ29: Service | AK29: Acct1($) | AL29: Acct2($)
A30: topn | B30: =VALUE(Dashboard!$W$5) | E30: =Service_List!$A$2 | F30: =IFERROR(INDEX(Service_List!$2:2,1,$B$28),0) | G30: =IFERROR(INDEX(Service_List!$2:2,1,$B$29),0) | H30: =F30-G30 | I30: =IFERROR(H30/G30,0) | J30: =RANK(F30,$F$30:$F$95,0) | K30: =ABS(H30) | L30: =RANK(K30,$K$30:$K$95,0) | N30: 1 | O30: =IFERROR(INDEX($E$30:$E$95,MATCH(1,$J$30:$J$95,0)),"") | P30: =IFERROR(INDEX($F$30:$F$95,MATCH(1,$J$30:$J$95,0)),0) | Q30: =IFERROR(INDEX($G$30:$G$95,MATCH(1,$J$30:$J$95,0)),0) | R30: =IFERROR(INDEX($H$30:$H$95,MATCH(1,$J$30:$J$95,0)),0) | S30: =IFERROR(INDEX($I$30:$I$95,MATCH(1,$J$30:$J$95,0)),0) | U30: 1 | V30: =IFERROR(INDEX($E$30:$E$95,MATCH(1,$L$30:$L$95,0)),"") | W30: =IFERROR(INDEX($F$30:$F$95,MATCH(1,$L$30:$L$95,0)),0) | X30: =IFERROR(INDEX($G$30:$G$95,MATCH(1,$L$30:$L$95,0)),0) | Y30: =IFERROR(INDEX($H$30:$H$95,MATCH(1,$L$30:$L$95,0)),0) | Z30: =IFERROR(INDEX($I$30:$I$95,MATCH(1,$L$30:$L$95,0)),0) | AB30: =IF(Months_Ref!$A$2="","",TEXT(Months_Ref!$A$2,"mmm-yy")) | AC30: =IFERROR(IF(Months_Ref!$A$2="",0,SUMPRODUCT((Acct1_Raw!$A$3:$A$26=Months_Ref!$A$2)*Acct1_Raw!$B$3:$BO$26)),0) | AD30: =IFERROR(IF(Months_Ref!$A$2="",0,SUMPRODUCT((Acct2_Raw!$A$3:$A$26=Months_Ref!$A$2)*Acct2_Raw!$B$3:$BO$26)),0) | AE30: =AC30+AD30 | AG30: =IFERROR(INDEX($E$30:$E$95,MATCH(1,$J$30:$J$95,0)),"") | AH30: =IFERROR(INDEX($F$30:$F$95,MATCH(1,$J$30:$J$95,0)),0) | AJ30: =IFERROR(INDEX($E$30:$E$95,MATCH(1,$J$30:$J$95,0)),"") | AK30: =IFERROR(INDEX(Service_List!$2:67,IFERROR(MATCH(IFERROR(INDEX($E$30:$E$95,MATCH(1,$J$30:$J$95,0)),""),Service_List!$A$2:$A$67,0),0),IFERROR(INDEX($B$2:$B$7,IFERROR(MATCH(Dashboard!$K$5,$A$2:$A$7,0),1)),2)),0) | AL30: =IFERROR(INDEX(Service_List!$2:67,IFERROR(MATCH(IFERROR(INDEX($E$30:$E$95,MATCH(1,$J$30:$J$95,0)),""),Service_List!$A$2:$A$67,0),0),IFERROR(INDEX($C$2:$C$7,IFERROR(MATCH(Dashboard!$K$5,$A$2:$A$7,0),1)),8)),0)
E31: =Service_List!$A$3 | F31: =IFERROR(INDEX(Service_List!$3:3,1,$B$28),0) | G31: =IFERROR(INDEX(Service_List!$3:3,1,$B$29),0) | H31: =F31-G31 | I31: =IFERROR(H31/G31,0) | J31: =RANK(F31,$F$30:$F$95,0) | K31: =ABS(H31) | L31: =RANK(K31,$K$30:$K$95,0) | N31: 2 | O31: =IFERROR(INDEX($E$30:$E$95,MATCH(2,$J$30:$J$95,0)),"") | P31: =IFERROR(INDEX($F$30:$F$95,MATCH(2,$J$30:$J$95,0)),0) | Q31: =IFERROR(INDEX($G$30:$G$95,MATCH(2,$J$30:$J$95,0)),0) | R31: =IFERROR(INDEX($H$30:$H$95,MATCH(2,$J$30:$J$95,0)),0) | S31: =IFERROR(INDEX($I$30:$I$95,MATCH(2,$J$30:$J$95,0)),0) | U31: 2 | V31: =IFERROR(INDEX($E$30:$E$95,MATCH(2,$L$30:$L$95,0)),"") | W31: =IFERROR(INDEX($F$30:$F$95,MATCH(2,$L$30:$L$95,0)),0) | X31: =IFERROR(INDEX($G$30:$G$95,MATCH(2,$L$30:$L$95,0)),0) | Y31: =IFERROR(INDEX($H$30:$H$95,MATCH(2,$L$30:$L$95,0)),0) | Z31: =IFERROR(INDEX($I$30:$I$95,MATCH(2,$L$30:$L$95,0)),0) | AB31: =IF(Months_Ref!$A$3="","",TEXT(Months_Ref!$A$3,"mmm-yy")) | AC31: =IFERROR(IF(Months_Ref!$A$3="",0,SUMPRODUCT((Acct1_Raw!$A$3:$A$26=Months_Ref!$A$3)*Acct1_Raw!$B$3:$BO$26)),0) | AD31: =IFERROR(IF(Months_Ref!$A$3="",0,SUMPRODUCT((Acct2_Raw!$A$3:$A$26=Months_Ref!$A$3)*Acct2_Raw!$B$3:$BO$26)),0) | AE31: =AC31+AD31 | AG31: =IFERROR(INDEX($E$30:$E$95,MATCH(2,$J$30:$J$95,0)),"") | AH31: =IFERROR(INDEX($F$30:$F$95,MATCH(2,$J$30:$J$95,0)),0) | AJ31: =IFERROR(INDEX($E$30:$E$95,MATCH(2,$J$30:$J$95,0)),"") | AK31: =IFERROR(INDEX(Service_List!$2:67,IFERROR(MATCH(IFERROR(INDEX($E$30:$E$95,MATCH(2,$J$30:$J$95,0)),""),Service_List!$A$2:$A$67,0),0),IFERROR(INDEX($B$2:$B$7,IFERROR(MATCH(Dashboard!$K$5,$A$2:$A$7,0),1)),2)),0) | AL31: =IFERROR(INDEX(Service_List!$2:67,IFERROR(MATCH(IFERROR(INDEX($E$30:$E$95,MATCH(2,$J$30:$J$95,0)),""),Service_List!$A$2:$A$67,0),0),IFERROR(INDEX($C$2:$C$7,IFERROR(MATCH(Dashboard!$K$5,$A$2:$A$7,0),1)),8)),0)
E32: =Service_List!$A$4 | F32: =IFERROR(INDEX(Service_List!$4:4,1,$B$28),0) | G32: =IFERROR(INDEX(Service_List!$4:4,1,$B$29),0) | H32: =F32-G32 | I32: =IFERROR(H32/G32,0) | J32: =RANK(F32,$F$30:$F$95,0) | K32: =ABS(H32) | L32: =RANK(K32,$K$30:$K$95,0) | N32: 3 | O32: =IFERROR(INDEX($E$30:$E$95,MATCH(3,$J$30:$J$95,0)),"") | P32: =IFERROR(INDEX($F$30:$F$95,MATCH(3,$J$30:$J$95,0)),0) | Q32: =IFERROR(INDEX($G$30:$G$95,MATCH(3,$J$30:$J$95,0)),0) | R32: =IFERROR(INDEX($H$30:$H$95,MATCH(3,$J$30:$J$95,0)),0) | S32: =IFERROR(INDEX($I$30:$I$95,MATCH(3,$J$30:$J$95,0)),0) | U32: 3 | V32: =IFERROR(INDEX($E$30:$E$95,MATCH(3,$L$30:$L$95,0)),"") | W32: =IFERROR(INDEX($F$30:$F$95,MATCH(3,$L$30:$L$95,0)),0) | X32: =IFERROR(INDEX($G$30:$G$95,MATCH(3,$L$30:$L$95,0)),0) | Y32: =IFERROR(INDEX($H$30:$H$95,MATCH(3,$L$30:$L$95,0)),0) | Z32: =IFERROR(INDEX($I$30:$I$95,MATCH(3,$L$30:$L$95,0)),0) | AB32: =IF(Months_Ref!$A$4="","",TEXT(Months_Ref!$A$4,"mmm-yy")) | AC32: =IFERROR(IF(Months_Ref!$A$4="",0,SUMPRODUCT((Acct1_Raw!$A$3:$A$26=Months_Ref!$A$4)*Acct1_Raw!$B$3:$BO$26)),0) | AD32: =IFERROR(IF(Months_Ref!$A$4="",0,SUMPRODUCT((Acct2_Raw!$A$3:$A$26=Months_Ref!$A$4)*Acct2_Raw!$B$3:$BO$26)),0) | AE32: =AC32+AD32 | AG32: =IFERROR(INDEX($E$30:$E$95,MATCH(3,$J$30:$J$95,0)),"") | AH32: =IFERROR(INDEX($F$30:$F$95,MATCH(3,$J$30:$J$95,0)),0) | AJ32: =IFERROR(INDEX($E$30:$E$95,MATCH(3,$J$30:$J$95,0)),"") | AK32: =IFERROR(INDEX(Service_List!$2:67,IFERROR(MATCH(IFERROR(INDEX($E$30:$E$95,MATCH(3,$J$30:$J$95,0)),""),Service_List!$A$2:$A$67,0),0),IFERROR(INDEX($B$2:$B$7,IFERROR(MATCH(Dashboard!$K$5,$A$2:$A$7,0),1)),2)),0) | AL32: =IFERROR(INDEX(Service_List!$2:67,IFERROR(MATCH(IFERROR(INDEX($E$30:$E$95,MATCH(3,$J$30:$J$95,0)),""),Service_List!$A$2:$A$67,0),0),IFERROR(INDEX($C$2:$C$7,IFERROR(MATCH(Dashboard!$K$5,$A$2:$A$7,0),1)),8)),0)
E33: =Service_List!$A$5 | F33: =IFERROR(INDEX(Service_List!$5:5,1,$B$28),0) | G33: =IFERROR(INDEX(Service_List!$5:5,1,$B$29),0) | H33: =F33-G33 | I33: =IFERROR(H33/G33,0) | J33: =RANK(F33,$F$30:$F$95,0) | K33: =ABS(H33) | L33: =RANK(K33,$K$30:$K$95,0) | N33: 4 | O33: =IFERROR(INDEX($E$30:$E$95,MATCH(4,$J$30:$J$95,0)),"") | P33: =IFERROR(INDEX($F$30:$F$95,MATCH(4,$J$30:$J$95,0)),0) | Q33: =IFERROR(INDEX($G$30:$G$95,MATCH(4,$J$30:$J$95,0)),0) | R33: =IFERROR(INDEX($H$30:$H$95,MATCH(4,$J$30:$J$95,0)),0) | S33: =IFERROR(INDEX($I$30:$I$95,MATCH(4,$J$30:$J$95,0)),0) | U33: 4 | V33: =IFERROR(INDEX($E$30:$E$95,MATCH(4,$L$30:$L$95,0)),"") | W33: =IFERROR(INDEX($F$30:$F$95,MATCH(4,$L$30:$L$95,0)),0) | X33: =IFERROR(INDEX($G$30:$G$95,MATCH(4,$L$30:$L$95,0)),0) | Y33: =IFERROR(INDEX($H$30:$H$95,MATCH(4,$L$30:$L$95,0)),0) | Z33: =IFERROR(INDEX($I$30:$I$95,MATCH(4,$L$30:$L$95,0)),0) | AB33: =IF(Months_Ref!$A$5="","",TEXT(Months_Ref!$A$5,"mmm-yy")) | AC33: =IFERROR(IF(Months_Ref!$A$5="",0,SUMPRODUCT((Acct1_Raw!$A$3:$A$26=Months_Ref!$A$5)*Acct1_Raw!$B$3:$BO$26)),0) | AD33: =IFERROR(IF(Months_Ref!$A$5="",0,SUMPRODUCT((Acct2_Raw!$A$3:$A$26=Months_Ref!$A$5)*Acct2_Raw!$B$3:$BO$26)),0) | AE33: =AC33+AD33 | AG33: =IFERROR(INDEX($E$30:$E$95,MATCH(4,$J$30:$J$95,0)),"") | AH33: =IFERROR(INDEX($F$30:$F$95,MATCH(4,$J$30:$J$95,0)),0) | AJ33: =IFERROR(INDEX($E$30:$E$95,MATCH(4,$J$30:$J$95,0)),"") | AK33: =IFERROR(INDEX(Service_List!$2:67,IFERROR(MATCH(IFERROR(INDEX($E$30:$E$95,MATCH(4,$J$30:$J$95,0)),""),Service_List!$A$2:$A$67,0),0),IFERROR(INDEX($B$2:$B$7,IFERROR(MATCH(Dashboard!$K$5,$A$2:$A$7,0),1)),2)),0) | AL33: =IFERROR(INDEX(Service_List!$2:67,IFERROR(MATCH(IFERROR(INDEX($E$30:$E$95,MATCH(4,$J$30:$J$95,0)),""),Service_List!$A$2:$A$67,0),0),IFERROR(INDEX($C$2:$C$7,IFERROR(MATCH(Dashboard!$K$5,$A$2:$A$7,0),1)),8)),0)
E34: =Service_List!$A$6 | F34: =IFERROR(INDEX(Service_List!$6:6,1,$B$28),0) | G34: =IFERROR(INDEX(Service_List!$6:6,1,$B$29),0) | H34: =F34-G34 | I34: =IFERROR(H34/G34,0) | J34: =RANK(F34,$F$30:$F$95,0) | K34: =ABS(H34) | L34: =RANK(K34,$K$30:$K$95,0) | N34: 5 | O34: =IFERROR(INDEX($E$30:$E$95,MATCH(5,$J$30:$J$95,0)),"") | P34: =IFERROR(INDEX($F$30:$F$95,MATCH(5,$J$30:$J$95,0)),0) | Q34: =IFERROR(INDEX($G$30:$G$95,MATCH(5,$J$30:$J$95,0)),0) | R34: =IFERROR(INDEX($H$30:$H$95,MATCH(5,$J$30:$J$95,0)),0) | S34: =IFERROR(INDEX($I$30:$I$95,MATCH(5,$J$30:$J$95,0)),0) | U34: 5 | V34: =IFERROR(INDEX($E$30:$E$95,MATCH(5,$L$30:$L$95,0)),"") | W34: =IFERROR(INDEX($F$30:$F$95,MATCH(5,$L$30:$L$95,0)),0) | X34: =IFERROR(INDEX($G$30:$G$95,MATCH(5,$L$30:$L$95,0)),0) | Y34: =IFERROR(INDEX($H$30:$H$95,MATCH(5,$L$30:$L$95,0)),0) | Z34: =IFERROR(INDEX($I$30:$I$95,MATCH(5,$L$30:$L$95,0)),0) | AB34: =IF(Months_Ref!$A$6="","",TEXT(Months_Ref!$A$6,"mmm-yy")) | AC34: =IFERROR(IF(Months_Ref!$A$6="",0,SUMPRODUCT((Acct1_Raw!$A$3:$A$26=Months_Ref!$A$6)*Acct1_Raw!$B$3:$BO$26)),0) | AD34: =IFERROR(IF(Months_Ref!$A$6="",0,SUMPRODUCT((Acct2_Raw!$A$3:$A$26=Months_Ref!$A$6)*Acct2_Raw!$B$3:$BO$26)),0) | AE34: =AC34+AD34 | AG34: =IFERROR(INDEX($E$30:$E$95,MATCH(5,$J$30:$J$95,0)),"") | AH34: =IFERROR(INDEX($F$30:$F$95,MATCH(5,$J$30:$J$95,0)),0) | AJ34: =IFERROR(INDEX($E$30:$E$95,MATCH(5,$J$30:$J$95,0)),"") | AK34: =IFERROR(INDEX(Service_List!$2:67,IFERROR(MATCH(IFERROR(INDEX($E$30:$E$95,MATCH(5,$J$30:$J$95,0)),""),Service_List!$A$2:$A$67,0),0),IFERROR(INDEX($B$2:$B$7,IFERROR(MATCH(Dashboard!$K$5,$A$2:$A$7,0),1)),2)),0) | AL34: =IFERROR(INDEX(Service_List!$2:67,IFERROR(MATCH(IFERROR(INDEX($E$30:$E$95,MATCH(5,$J$30:$J$95,0)),""),Service_List!$A$2:$A$67,0),0),IFERROR(INDEX($C$2:$C$7,IFERROR(MATCH(Dashboard!$K$5,$A$2:$A$7,0),1)),8)),0)
E35: =Service_List!$A$7 | F35: =IFERROR(INDEX(Service_List!$7:7,1,$B$28),0) | G35: =IFERROR(INDEX(Service_List!$7:7,1,$B$29),0) | H35: =F35-G35 | I35: =IFERROR(H35/G35,0) | J35: =RANK(F35,$F$30:$F$95,0) | K35: =ABS(H35) | L35: =RANK(K35,$K$30:$K$95,0) | N35: 6 | O35: =IFERROR(INDEX($E$30:$E$95,MATCH(6,$J$30:$J$95,0)),"") | P35: =IFERROR(INDEX($F$30:$F$95,MATCH(6,$J$30:$J$95,0)),0) | Q35: =IFERROR(INDEX($G$30:$G$95,MATCH(6,$J$30:$J$95,0)),0) | R35: =IFERROR(INDEX($H$30:$H$95,MATCH(6,$J$30:$J$95,0)),0) | S35: =IFERROR(INDEX($I$30:$I$95,MATCH(6,$J$30:$J$95,0)),0) | U35: 6 | V35: =IFERROR(INDEX($E$30:$E$95,MATCH(6,$L$30:$L$95,0)),"") | W35: =IFERROR(INDEX($F$30:$F$95,MATCH(6,$L$30:$L$95,0)),0) | X35: =IFERROR(INDEX($G$30:$G$95,MATCH(6,$L$30:$L$95,0)),0) | Y35: =IFERROR(INDEX($H$30:$H$95,MATCH(6,$L$30:$L$95,0)),0) | Z35: =IFERROR(INDEX($I$30:$I$95,MATCH(6,$L$30:$L$95,0)),0) | AB35: =IF(Months_Ref!$A$7="","",TEXT(Months_Ref!$A$7,"mmm-yy")) | AC35: =IFERROR(IF(Months_Ref!$A$7="",0,SUMPRODUCT((Acct1_Raw!$A$3:$A$26=Months_Ref!$A$7)*Acct1_Raw!$B$3:$BO$26)),0) | AD35: =IFERROR(IF(Months_Ref!$A$7="",0,SUMPRODUCT((Acct2_Raw!$A$3:$A$26=Months_Ref!$A$7)*Acct2_Raw!$B$3:$BO$26)),0) | AE35: =AC35+AD35 | AG35: =IFERROR(INDEX($E$30:$E$95,MATCH(6,$J$30:$J$95,0)),"") | AH35: =IFERROR(INDEX($F$30:$F$95,MATCH(6,$J$30:$J$95,0)),0) | AJ35: =IFERROR(INDEX($E$30:$E$95,MATCH(6,$J$30:$J$95,0)),"") | AK35: =IFERROR(INDEX(Service_List!$2:67,IFERROR(MATCH(IFERROR(INDEX($E$30:$E$95,MATCH(6,$J$30:$J$95,0)),""),Service_List!$A$2:$A$67,0),0),IFERROR(INDEX($B$2:$B$7,IFERROR(MATCH(Dashboard!$K$5,$A$2:$A$7,0),1)),2)),0) | AL35: =IFERROR(INDEX(Service_List!$2:67,IFERROR(MATCH(IFERROR(INDEX($E$30:$E$95,MATCH(6,$J$30:$J$95,0)),""),Service_List!$A$2:$A$67,0),0),IFERROR(INDEX($C$2:$C$7,IFERROR(MATCH(Dashboard!$K$5,$A$2:$A$7,0),1)),8)),0)
E36: =Service_List!$A$8 | F36: =IFERROR(INDEX(Service_List!$8:8,1,$B$28),0) | G36: =IFERROR(INDEX(Service_List!$8:8,1,$B$29),0) | H36: =F36-G36 | I36: =IFERROR(H36/G36,0) | J36: =RANK(F36,$F$30:$F$95,0) | K36: =ABS(H36) | L36: =RANK(K36,$K$30:$K$95,0) | N36: 7 | O36: =IFERROR(INDEX($E$30:$E$95,MATCH(7,$J$30:$J$95,0)),"") | P36: =IFERROR(INDEX($F$30:$F$95,MATCH(7,$J$30:$J$95,0)),0) | Q36: =IFERROR(INDEX($G$30:$G$95,MATCH(7,$J$30:$J$95,0)),0) | R36: =IFERROR(INDEX($H$30:$H$95,MATCH(7,$J$30:$J$95,0)),0) | S36: =IFERROR(INDEX($I$30:$I$95,MATCH(7,$J$30:$J$95,0)),0) | U36: 7 | V36: =IFERROR(INDEX($E$30:$E$95,MATCH(7,$L$30:$L$95,0)),"") | W36: =IFERROR(INDEX($F$30:$F$95,MATCH(7,$L$30:$L$95,0)),0) | X36: =IFERROR(INDEX($G$30:$G$95,MATCH(7,$L$30:$L$95,0)),0) | Y36: =IFERROR(INDEX($H$30:$H$95,MATCH(7,$L$30:$L$95,0)),0) | Z36: =IFERROR(INDEX($I$30:$I$95,MATCH(7,$L$30:$L$95,0)),0) | AG36: =IFERROR(INDEX($E$30:$E$95,MATCH(7,$J$30:$J$95,0)),"") | AH36: =IFERROR(INDEX($F$30:$F$95,MATCH(7,$J$30:$J$95,0)),0) | AJ36: =IFERROR(INDEX($E$30:$E$95,MATCH(7,$J$30:$J$95,0)),"") | AK36: =IFERROR(INDEX(Service_List!$2:67,IFERROR(MATCH(IFERROR(INDEX($E$30:$E$95,MATCH(7,$J$30:$J$95,0)),""),Service_List!$A$2:$A$67,0),0),IFERROR(INDEX($B$2:$B$7,IFERROR(MATCH(Dashboard!$K$5,$A$2:$A$7,0),1)),2)),0) | AL36: =IFERROR(INDEX(Service_List!$2:67,IFERROR(MATCH(IFERROR(INDEX($E$30:$E$95,MATCH(7,$J$30:$J$95,0)),""),Service_List!$A$2:$A$67,0),0),IFERROR(INDEX($C$2:$C$7,IFERROR(MATCH(Dashboard!$K$5,$A$2:$A$7,0),1)),8)),0)
